Workbook

Sheet Sheet1
A1: 수질TMS정도검사 시트 | R1: v 9.0 청정수소인증센터 (2025.02.18)
D3: 총유기탄소 | G3: 총질소 | K3: 총인 | O3: 부유물질 | S3: 수소이온농도 | Y3: 용존산소 | AE3: 화학적산소요구량
A7: O Test Condition
A8: 측정범위 | D8: 0 | E8: ~ | G8: 0 | H8: ~ | K8: 0 | L8: ~ | O8: 0 | P8: ~ | S8: pH0 ~ pH14 | Y8: 0 ~ 20 | AE8: 0 | AF8: ~
Y9: 수질오염공정시험기준 표2. 용존산소포화량
Y10: 25 ℃ Span | Z10: 8.263 | AA10: 20℃ Span | AB10: 9.092 | AC10: 30℃ Span | AD10: 7.559
A11: O DATA Sheet
A12: 직선성 | C12: M1 | G12: M1 | K12: M1 | O12: M1 | S12: 반복성 | T12: 7 | Y12: 반복성 | Z12: S | AE12: M1
C13: M2 | G13: M2 | K13: M2 | O13: M2 | T13: 4 | AE13: M2
C14: M3 | G14: M3 | K14: M3 | O14: M3 | T14: 7 | Z14: S | AE14: M3
A15: 드리프트 | B15: 시험 초기 | C15: Z1 | G15: Z1 | K15: Z1 | O15: Z1 | T15: 4 | AE15: Z1
C16: Z2 | G16: Z2 | K16: Z2 | O16: Z2 | T16: 7 | Z16: S | AE16: Z2
C17: S1 | G17: S1 | K17: S1 | O17: S1 | T17: 4 | AE17: S1
C18: S2 | G18: S2 | K18: S2 | O18: S2 | S18: 드리프트 (초기) | T18: 4 | V18: 드리프트 (2시간 이후) | W18: 4 | Y18: 드리프트 (초기) | Z18: Z | AB18: 드리프트 (2시간 이후) | AC18: Z | AE18: S2
B19: Z(4hr) | T19: 4 | W19: 4 | Z19: Z | AC19: Z | AE19: Z(4hr)
B20: 4시간 이후 | C20: Z3 | G20: Z3 | K20: Z3 | O20: Z3 | T20: 4 | W20: 4 | Z20: Z | AC20: Z | AE20: Z3
C21: Z4 | G21: Z4 | K21: Z4 | O21: Z4 | T21: 7 | W21: 7 | Z21: S | AC21: S | AE21: Z4
C22: S3 | G22: S3 | K22: S3 | O22: S3 | T22: 7 | W22: 7 | Z22: S | AC22: S | AE22: S3
C23: S4 | G23: S4 | K23: S4 | O23: S4 | T23: 7 | W23: 7 | Z23: S | AC23: S | AE23: S4
B24: 응답시간 | S24: 직선성
A25: 반복성 | C25: Z5 | G25: Z5 | K25: Z5 | O25: Z5 | S25: 4 | U25: 7 | W25: 10 | AE25: Z5
C26: S5 | G26: S5 | K26: S5 | O26: S5 | S26: 4 | U26: 7 | W26: 10 | AE26: S5
C27: Z | D27: =IFERROR(IF(MAX(STDEV(D15,D20,D25),STDEV(D16,D21,D25),STDEV(D15,D21,D25),STDEV(D16,D20,D25))=(STDEV(D15,D20,D25)),D15,IF(MAX(STDEV(D15,D20,D25),STDEV(D16,D21,D25),STDEV(D15,D21,D25),STDEV(D16,D20,D25))=(STDEV(D15,D21,D25)),D15,IF(MAX(STDEV(D15,D20,D25),STDEV(D16,D21,D25),STDEV(D15,D21,D25),STDEV(D16,D20,D25))=(STDEV(D16,D21,D25)),D16,IF(MAX(STDEV(D15,D20,D25),STDEV(D16,D21,D25),STDEV(D15,D21,D25),STDEV(D16,D20,D25))=(STDEV(D16,D20,D25)),D16)))),"") | G27: Z | H27: =IFERROR(IF(MAX(STDEV(H15,H20,H25),STDEV(H16,H21,H25),STDEV(H15,H21,H25),STDEV(H16,H20,H25))=(STDEV(H15,H20,H25)),H15,IF(MAX(STDEV(H15,H20,H25),STDEV(H16,H21,H25),STDEV(H15,H21,H25),STDEV(H16,H20,H25))=(STDEV(H15,H21,H25)),H15,IF(MAX(STDEV(H15,H20,H25),STDEV(H16,H21,H25),STDEV(H15,H21,H25),STDEV(H16,H20,H25))=(STDEV(H16,H21,H25)),H16,IF(MAX(STDEV(H15,H20,H25),STDEV(H16,H21,H25),STDEV(H15,H21,H25),STDEV(H16,H20,H25))=(STDEV(H16,H20,H25)),H16)))),"") | K27: Z | L27: =IFERROR(IF(MAX(STDEV(L15,L20,L25),STDEV(L16,L21,L25),STDEV(L15,L21,L25),STDEV(L16,L20,L25))=(STDEV(L15,L20,L25)),L15,IF(MAX(STDEV(L15,L20,L25),STDEV(L16,L21,L25),STDEV(L15,L21,L25),STDEV(L16,L20,L25))=(STDEV(L15,L21,L25)),L15,IF(MAX(STDEV(L15,L20,L25),STDEV(L16,L21,L25),STDEV(L15,L21,L25),STDEV(L16,L20,L25))=(STDEV(L16,L21,L25)),L16,IF(MAX(STDEV(L15,L20,L25),STDEV(L16,L21,L25),STDEV(L15,L21,L25),STDEV(L16,L20,L25))=(STDEV(L16,L20,L25)),L16)))),"") | O27: Z | P27: =IFERROR(IF(MAX(STDEV(P15,P20,P25),STDEV(P16,P21,P25),STDEV(P15,P21,P25),STDEV(P16,P20,P25))=(STDEV(P15,P20,P25)),P15,IF(MAX(STDEV(P15,P20,P25),STDEV(P16,P21,P25),STDEV(P15,P21,P25),STDEV(P16,P20,P25))=(STDEV(P15,P21,P25)),P15,IF(MAX(STDEV(P15,P20,P25),STDEV(P16,P21,P25),STDEV(P15,P21,P25),STDEV(P16,P20,P25))=(STDEV(P16,P21,P25)),P16,IF(MAX(STDEV(P15,P20,P25),STDEV(P16,P21,P25),STDEV(P15,P21,P25),STDEV(P16,P20,P25))=(STDEV(P16,P20,P25)),P16)))),"") | S27: 4 | U27: 7 | W27: 10 | AE27: Z | AF27: =IFERROR(IF(MAX(STDEV(AF15,AF20,AF25),STDEV(AF16,AF21,AF25),STDEV(AF15,AF21,AF25),STDEV(AF16,AF20,AF25))=(STDEV(AF15,AF20,AF25)),AF15,IF(MAX(STDEV(AF15,AF20,AF25),STDEV(AF16,AF21,AF25),STDEV(AF15,AF21,AF25),STDEV(AF16,AF20,AF25))=(STDEV(AF15,AF21,AF25)),AF15,IF(MAX(STDEV(AF15,AF20,AF25),STDEV(AF16,AF21,AF25),STDEV(AF15,AF21,AF25),STDEV(AF16,AF20,AF25))=(STDEV(AF16,AF21,AF25)),AF16,IF(MAX(STDEV(AF15,AF20,AF25),STDEV(AF16,AF21,AF25),STDEV(AF15,AF21,AF25),STDEV(AF16,AF20,AF25))=(STDEV(AF16,AF20,AF25)),AF16)))),"")
C28: S | D28: =IFERROR(IF(MAX(STDEV(D17,D22,D26),STDEV(D18,D23,D26),STDEV(D17,D23,D26),STDEV(D18,D22,D26))=(STDEV(D17,D22,D26)),D17,IF(MAX(STDEV(D17,D22,D26),STDEV(D18,D23,D26),STDEV(D17,D23,D26),STDEV(D18,D22,D26))=(STDEV(D17,D23,D26)),D17,IF(MAX(STDEV(D17,D22,D26),STDEV(D18,D23,D26),STDEV(D17,D23,D26),STDEV(D18,D22,D26))=(STDEV(D18,D23,D26)),D18,IF(MAX(STDEV(D17,D22,D26),STDEV(D18,D23,D26),STDEV(D17,D23,D26),STDEV(D18,D22,D26))=(STDEV(D18,D22,D26)),D18)))),"") | G28: S | H28: =IFERROR(IF(MAX(STDEV(H17,H22,H26),STDEV(H18,H23,H26),STDEV(H17,H23,H26),STDEV(H18,H22,H26))=(STDEV(H17,H22,H26)),H17,IF(MAX(STDEV(H17,H22,H26),STDEV(H18,H23,H26),STDEV(H17,H23,H26),STDEV(H18,H22,H26))=(STDEV(H17,H23,H26)),H17,IF(MAX(STDEV(H17,H22,H26),STDEV(H18,H23,H26),STDEV(H17,H23,H26),STDEV(H18,H22,H26))=(STDEV(H18,H23,H26)),H18,IF(MAX(STDEV(H17,H22,H26),STDEV(H18,H23,H26),STDEV(H17,H23,H26),STDEV(H18,H22,H26))=(STDEV(H18,H22,H26)),H18)))),"") | K28: S | L28: =IFERROR(IF(MAX(STDEV(L17,L22,L26),STDEV(L18,L23,L26),STDEV(L17,L23,L26),STDEV(L18,L22,L26))=(STDEV(L17,L22,L26)),L17,IF(MAX(STDEV(L17,L22,L26),STDEV(L18,L23,L26),STDEV(L17,L23,L26),STDEV(L18,L22,L26))=(STDEV(L17,L23,L26)),L17,IF(MAX(STDEV(L17,L22,L26),STDEV(L18,L23,L26),STDEV(L17,L23,L26),STDEV(L18,L22,L26))=(STDEV(L18,L23,L26)),L18,IF(MAX(STDEV(L17,L22,L26),STDEV(L18,L23,L26),STDEV(L17,L23,L26),STDEV(L18,L22,L26))=(STDEV(L18,L22,L26)),L18)))),"") | O28: S | P28: =IFERROR(IF(MAX(STDEV(P17,P22,P26),STDEV(P18,P23,P26),STDEV(P17,P23,P26),STDEV(P18,P22,P26))=(STDEV(P17,P22,P26)),P17,IF(MAX(STDEV(P17,P22,P26),STDEV(P18,P23,P26),STDEV(P17,P23,P26),STDEV(P18,P22,P26))=(STDEV(P17,P23,P26)),P17,IF(MAX(STDEV(P17,P22,P26),STDEV(P18,P23,P26),STDEV(P17,P23,P26),STDEV(P18,P22,P26))=(STDEV(P18,P23,P26)),P18,IF(MAX(STDEV(P17,P22,P26),STDEV(P18,P23,P26),STDEV(P17,P23,P26),STDEV(P18,P22,P26))=(STDEV(P18,P22,P26)),P18)))),"") | S28: 온도보상시험 (4.00) | T28: 10℃ | V28: 25℃ | AE28: S | AF28: =IFERROR(IF(MAX(STDEV(AF17,AF22,AF26),STDEV(AF18,AF23,AF26),STDEV(AF17,AF23,AF26),STDEV(AF18,AF22,AF26))=(STDEV(AF17,AF22,AF26)),AF17,IF(MAX(STDEV(AF17,AF22,AF26),STDEV(AF18,AF23,AF26),STDEV(AF17,AF23,AF26),STDEV(AF18,AF22,AF26))=(STDEV(AF17,AF23,AF26)),AF17,IF(MAX(STDEV(AF17,AF22,AF26),STDEV(AF18,AF23,AF26),STDEV(AF17,AF23,AF26),STDEV(AF18,AF22,AF26))=(STDEV(AF18,AF23,AF26)),AF18,IF(MAX(STDEV(AF17,AF22,AF26),STDEV(AF18,AF23,AF26),STDEV(AF17,AF23,AF26),STDEV(AF18,AF22,AF26))=(STDEV(AF18,AF22,AF26)),AF18)))),"")
C29: Z | D29: =IFERROR(IF(MAX(STDEV(D15,D20,D25),STDEV(D16,D21,D25),STDEV(D15,D21,D25),STDEV(D16,D20,D25))=(STDEV(D15,D20,D25)),D20,IF(MAX(STDEV(D15,D20,D25),STDEV(D16,D21,D25),STDEV(D15,D21,D25),STDEV(D16,D20,D25))=(STDEV(D15,D21,D25)),D21,IF(MAX(STDEV(D15,D20,D25),STDEV(D16,D21,D25),STDEV(D15,D21,D25),STDEV(D16,D20,D25))=(STDEV(D16,D21,D25)),D21,IF(MAX(STDEV(D15,D20,D25),STDEV(D16,D21,D25),STDEV(D15,D21,D25),STDEV(D16,D20,D25))=(STDEV(D16,D20,D25)),D20)))),"") | G29: Z | H29: =IFERROR(IF(MAX(STDEV(H15,H20,H25),STDEV(H16,H21,H25),STDEV(H15,H21,H25),STDEV(H16,H20,H25))=(STDEV(H15,H20,H25)),H20,IF(MAX(STDEV(H15,H20,H25),STDEV(H16,H21,H25),STDEV(H15,H21,H25),STDEV(H16,H20,H25))=(STDEV(H15,H21,H25)),H21,IF(MAX(STDEV(H15,H20,H25),STDEV(H16,H21,H25),STDEV(H15,H21,H25),STDEV(H16,H20,H25))=(STDEV(H16,H21,H25)),H21,IF(MAX(STDEV(H15,H20,H25),STDEV(H16,H21,H25),STDEV(H15,H21,H25),STDEV(H16,H20,H25))=(STDEV(H16,H20,H25)),H20)))),"") | K29: Z | L29: =IFERROR(IF(MAX(STDEV(L15,L20,L25),STDEV(L16,L21,L25),STDEV(L15,L21,L25),STDEV(L16,L20,L25))=(STDEV(L15,L20,L25)),L20,IF(MAX(STDEV(L15,L20,L25),STDEV(L16,L21,L25),STDEV(L15,L21,L25),STDEV(L16,L20,L25))=(STDEV(L15,L21,L25)),L21,IF(MAX(STDEV(L15,L20,L25),STDEV(L16,L21,L25),STDEV(L15,L21,L25),STDEV(L16,L20,L25))=(STDEV(L16,L21,L25)),L21,IF(MAX(STDEV(L15,L20,L25),STDEV(L16,L21,L25),STDEV(L15,L21,L25),STDEV(L16,L20,L25))=(STDEV(L16,L20,L25)),L20)))),"") | O29: Z | P29: =IFERROR(IF(MAX(STDEV(P15,P20,P25),STDEV(P16,P21,P25),STDEV(P15,P21,P25),STDEV(P16,P20,P25))=(STDEV(P15,P20,P25)),P20,IF(MAX(STDEV(P15,P20,P25),STDEV(P16,P21,P25),STDEV(P15,P21,P25),STDEV(P16,P20,P25))=(STDEV(P15,P21,P25)),P21,IF(MAX(STDEV(P15,P20,P25),STDEV(P16,P21,P25),STDEV(P15,P21,P25),STDEV(P16,P20,P25))=(STDEV(P16,P21,P25)),P21,IF(MAX(STDEV(P15,P20,P25),STDEV(P16,P21,P25),STDEV(P15,P21,P25),STDEV(P16,P20,P25))=(STDEV(P16,P20,P25)),P20)))),"") | T29: 15℃ | V29: 30℃ | Y29: 응답시간 | AA29: 120 초 | AE29: Z | AF29: =IFERROR(IF(MAX(STDEV(AF15,AF20,AF25),STDEV(AF16,AF21,AF25),STDEV(AF15,AF21,AF25),STDEV(AF16,AF20,AF25))=(STDEV(AF15,AF20,AF25)),AF20,IF(MAX(STDEV(AF15,AF20,AF25),STDEV(AF16,AF21,AF25),STDEV(AF15,AF21,AF25),STDEV(AF16,AF20,AF25))=(STDEV(AF15,AF21,AF25)),AF21,IF(MAX(STDEV(AF15,AF20,AF25),STDEV(AF16,AF21,AF25),STDEV(AF15,AF21,AF25),STDEV(AF16,AF20,AF25))=(STDEV(AF16,AF21,AF25)),AF21,IF(MAX(STDEV(AF15,AF20,AF25),STDEV(AF16,AF21,AF25),STDEV(AF15,AF21,AF25),STDEV(AF16,AF20,AF25))=(STDEV(AF16,AF20,AF25)),AF20)))),"")
C30: S | D30: =IFERROR(IF(MAX(STDEV(D17,D22,D26),STDEV(D18,D23,D26),STDEV(D17,D23,D26),STDEV(D18,D22,D26))=(STDEV(D17,D22,D26)),D22,IF(MAX(STDEV(D17,D22,D26),STDEV(D18,D23,D26),STDEV(D17,D23,D26),STDEV(D18,D22,D26))=(STDEV(D17,D23,D26)),D23,IF(MAX(STDEV(D17,D22,D26),STDEV(D18,D23,D26),STDEV(D17,D23,D26),STDEV(D18,D22,D26))=(STDEV(D18,D23,D26)),D23,IF(MAX(STDEV(D17,D22,D26),STDEV(D18,D23,D26),STDEV(D17,D23,D26),STDEV(D18,D22,D26))=(STDEV(D18,D22,D26)),D22)))),"") | G30: S | H30: =IFERROR(IF(MAX(STDEV(H17,H22,H26),STDEV(H18,H23,H26),STDEV(H17,H23,H26),STDEV(H18,H22,H26))=(STDEV(H17,H22,H26)),H22,IF(MAX(STDEV(H17,H22,H26),STDEV(H18,H23,H26),STDEV(H17,H23,H26),STDEV(H18,H22,H26))=(STDEV(H17,H23,H26)),H23,IF(MAX(STDEV(H17,H22,H26),STDEV(H18,H23,H26),STDEV(H17,H23,H26),STDEV(H18,H22,H26))=(STDEV(H18,H23,H26)),H23,IF(MAX(STDEV(H17,H22,H26),STDEV(H18,H23,H26),STDEV(H17,H23,H26),STDEV(H18,H22,H26))=(STDEV(H18,H22,H26)),H22)))),"") | K30: S | L30: =IFERROR(IF(MAX(STDEV(L17,L22,L26),STDEV(L18,L23,L26),STDEV(L17,L23,L26),STDEV(L18,L22,L26))=(STDEV(L17,L22,L26)),L22,IF(MAX(STDEV(L17,L22,L26),STDEV(L18,L23,L26),STDEV(L17,L23,L26),STDEV(L18,L22,L26))=(STDEV(L17,L23,L26)),L23,IF(MAX(STDEV(L17,L22,L26),STDEV(L18,L23,L26),STDEV(L17,L23,L26),STDEV(L18,L22,L26))=(STDEV(L18,L23,L26)),L23,IF(MAX(STDEV(L17,L22,L26),STDEV(L18,L23,L26),STDEV(L17,L23,L26),STDEV(L18,L22,L26))=(STDEV(L18,L22,L26)),L22)))),"") | O30: S | P30: =IFERROR(IF(MAX(STDEV(P17,P22,P26),STDEV(P18,P23,P26),STDEV(P17,P23,P26),STDEV(P18,P22,P26))=(STDEV(P17,P22,P26)),P22,IF(MAX(STDEV(P17,P22,P26),STDEV(P18,P23,P26),STDEV(P17,P23,P26),STDEV(P18,P22,P26))=(STDEV(P17,P23,P26)),P23,IF(MAX(STDEV(P17,P22,P26),STDEV(P18,P23,P26),STDEV(P17,P23,P26),STDEV(P18,P22,P26))=(STDEV(P18,P23,P26)),P23,IF(MAX(STDEV(P17,P22,P26),STDEV(P18,P23,P26),STDEV(P17,P23,P26),STDEV(P18,P22,P26))=(STDEV(P18,P22,P26)),P22)))),"") | T30: 20℃ | V30: 응답시간 | W30: 30 초 | Y30: 온도보상시험 | AA30: 20 ℃ | AE30: S | AF30: =IFERROR(IF(MAX(STDEV(AF17,AF22,AF26),STDEV(AF18,AF23,AF26),STDEV(AF17,AF23,AF26),STDEV(AF18,AF22,AF26))=(STDEV(AF17,AF22,AF26)),AF22,IF(MAX(STDEV(AF17,AF22,AF26),STDEV(AF18,AF23,AF26),STDEV(AF17,AF23,AF26),STDEV(AF18,AF22,AF26))=(STDEV(AF17,AF23,AF26)),AF23,IF(MAX(STDEV(AF17,AF22,AF26),STDEV(AF18,AF23,AF26),STDEV(AF17,AF23,AF26),STDEV(AF18,AF22,AF26))=(STDEV(AF18,AF23,AF26)),AF23,IF(MAX(STDEV(AF17,AF22,AF26),STDEV(AF18,AF23,AF26),STDEV(AF17,AF23,AF26),STDEV(AF18,AF22,AF26))=(STDEV(AF18,AF22,AF26)),AF22)))),"")
A31: 현장적용 계수시험 | D31: 측정값 | H31: 측정값 | L31: 측정값 | P31: 측정값 | S31: 현장적용 계수시험 | U31: 측정값 | W31: 주시험 | AA31: 20 ℃ | AF31: 측정값
C32: 1 | G32: 1 | K32: 1 | O32: 1 | AA32: 20 ℃ | AE32: 1
AA33: 30 ℃
C34: 2 | G34: 2 | K34: 2 | O34: 2 | AA34: 30 ℃ | AE34: 2
AA35: 30 ℃
A36: 성능확인 계산 | C36: TOC Data | G36: TN Data | K36: TP Data | O36: SS Data | S36: pH Data | Y36: DO Data | AE36: COD Data
C37: Z5 | D37: =IF(OR(ISBLANK(D25), ISTEXT(D25)), "", D25) | E37: S5 | F37: =IF(OR(ISBLANK(D26), ISTEXT(D26)), "", D26) | G37: Z5 | H37: =IF(OR(ISBLANK(H25), ISTEXT(H25)), "", H25) | I37: S5 | J37: =IF(OR(ISBLANK(H26), ISTEXT(H26)), "", H26) | K37: Z5 | L37: =IF(OR(ISBLANK(L25), ISTEXT(L25)), "", L25) | M37: S5 | N37: =IF(OR(ISBLANK(L26), ISTEXT(L26)), "", L26) | O37: Z5 | P37: =IF(OR(ISBLANK(P25), ISTEXT(P25)), "", P25) | Q37: S5 | R37: =IF(OR(ISBLANK(P26), ISTEXT(P26)), "", P26) | S37: 7 | T37: =IF(OR(ISBLANK(U12), ISTEXT(U12)), "", U12) | U37: 4 | V37: =IF(OR(ISBLANK(U13), ISTEXT(U13)), "", U13) | Y37: =Z10 -> 8.263 | Z37: =IF(OR(ISBLANK(AA12), ISTEXT(AA12)), "", AA12) | AE37: Z5 | AF37: =IF(OR(ISBLANK(AF25), ISTEXT(AF25)), "", AF25) | AG37: S5 | AH37: =IF(OR(ISBLANK(AF26), ISTEXT(AF26)), "", AF26)
C38: =IF(D27=D15,"Z1","Z2") -> Z1 | D38: =IF(OR(ISBLANK(D27), ISTEXT(D27)), "", D27) | E38: =IF(D28=D17,"S1","S2") -> S1 | F38: =IF(OR(ISBLANK(D28), ISTEXT(D28)), "", D28) | G38: =IF(H27=H15,"Z1","Z2") -> Z1 | H38: =IF(OR(ISBLANK(H27), ISTEXT(H27)), "", H27) | I38: =IF(H28=H17,"S1","S2") -> S1 | J38: =IF(OR(ISBLANK(H28), ISTEXT(H28)), "", H28) | K38: =IF(L27=L15,"Z1","Z2") -> Z1 | L38: =IF(OR(ISBLANK(L27), ISTEXT(L27)), "", L27) | M38: =IF(L28=L17,"S1","S2") -> S1 | N38: =IF(OR(ISBLANK(L28), ISTEXT(L28)), "", L28) | O38: =IF(P27=P15,"Z1","Z2") -> Z1 | P38: =IF(OR(ISBLANK(P27), ISTEXT(P27)), "", P27) | Q38: =IF(P28=P17,"S1","S2") -> S1 | R38: =IF(OR(ISBLANK(P28), ISTEXT(P28)), "", P28) | S38: 7 | T38: =IF(OR(ISBLANK(U14), ISTEXT(U14)), "", U14) | U38: 4 | V38: =IF(OR(ISBLANK(U15), ISTEXT(U15)), "", U15) | Z38: =IF(OR(ISBLANK(AA14), ISTEXT(AA14)), "", AA14) | AE38: =IF(AF27=AF15,"Z1","Z2") -> Z1 | AF38: =IF(OR(ISBLANK(AF27), ISTEXT(AF27)), "", AF27) | AG38: =IF(AF28=AF17,"S1","S2") -> S1 | AH38: =IF(OR(ISBLANK(AF28), ISTEXT(AF28)), "", AF28)
C39: =IF(D29=D20,"Z3","Z4") -> Z3 | D39: =IF(OR(ISBLANK(D29), ISTEXT(D29)), "", D29) | E39: =IF(D30=D22,"S3","S4") -> S3 | F39: =IF(OR(ISBLANK(D30), ISTEXT(D30)), "", D30) | G39: =IF(H29=H20,"Z3","Z4") -> Z3 | H39: =IF(OR(ISBLANK(H29), ISTEXT(H29)), "", H29) | I39: =IF(H30=H22,"S3","S4") -> S3 | J39: =IF(OR(ISBLANK(H30), ISTEXT(H30)), "", H30) | K39: =IF(L29=L20,"Z3","Z4") -> Z3 | L39: =IF(OR(ISBLANK(L29), ISTEXT(L29)), "", L29) | M39: =IF(L30=L22,"S3","S4") -> S3 | N39: =IF(OR(ISBLANK(L30), ISTEXT(L30)), "", L30) | O39: =IF(P29=P20,"Z3","Z4") -> Z3 | P39: =IF(OR(ISBLANK(P29), ISTEXT(P29)), "", P29) | Q39: =IF(P30=P22,"S3","S4") -> S3 | R39: =IF(OR(ISBLANK(P30), ISTEXT(P30)), "", P30) | S39: 7 | T39: =IF(OR(ISBLANK(U16), ISTEXT(U16)), "", U16) | U39: 4 | V39: =IF(OR(ISBLANK(U17), ISTEXT(U17)), "", U17) | Z39: =IF(OR(ISBLANK(AA16), ISTEXT(AA16)), "", AA16) | AE39: =IF(AF29=AF20,"Z3","Z4") -> Z3 | AF39: =IF(OR(ISBLANK(AF29), ISTEXT(AF29)), "", AF29) | AG39: =IF(AF30=AF22,"S3","S4") -> S3 | AH39: =IF(OR(ISBLANK(AF30), ISTEXT(AF30)), "", AF30)
C40: 반복성 | D40: =IF( OR( COUNTBLANK(D37:D39)>0, COUNTBLANK(F37:F39)>0, F8=0, ISBLANK(F8) ), "", ROUND(MAX(STDEV(D37:D39), STDEV(F37:F39))/F8*100, 1) ) | E40: 결과 | F40: =IF( OR( ISBLANK(D40), ISTEXT(D40), NOT(ISNUMBER(D40)), D40 > 3 ), "부적합", "적 합" ) -> 부적합 | G40: 반복성 | H40: =IF( OR( COUNTBLANK(H37:H39) > 0, COUNTBLANK(J37:J39) > 0, J8 = 0, ISBLANK(J8) ), "", ROUND(MAX(STDEV(H37:H39), STDEV(J37:J39)) / J8 * 100, 1) ) | I40: 결과 | J40: =IF( OR( ISBLANK(H40), ISTEXT(H40), NOT(ISNUMBER(H40)), H40 > 3 ), "부적합", "적 합" ) -> 부적합 | K40: 반복성 | L40: =IF( OR( COUNTBLANK(L37:L39) > 0, COUNTBLANK(N37:N39) > 0, N8 = 0, ISBLANK(N8) ), "", ROUND(MAX(STDEV(L37:L39), STDEV(N37:N39)) / N8 * 100, 1) ) | M40: 결과 | N40: =IF( OR( ISBLANK(L40), ISTEXT(L40), ISERROR(L40), L40 > 3 ), "부적합", IF(AND(L40 <= 3, ISNUMBER(L40)), "적 합", "부적합") ) -> 부적합 | O40: 반복성 | P40: =IF( OR( COUNTBLANK(P37:P39) > 0, COUNTBLANK(R37:R39) > 0, R8 = 0, ISBLANK(R8) ), "", ROUND(MAX(STDEV(P37:P39), STDEV(R37:R39)) / R8 * 100, 1) ) | Q40: 결과 | R40: =IF( OR( ISBLANK(P40), ISTEXT(P40), ISERROR(P40), P40 > 3 ), "부적합", IF(AND(P40 <= 3, ISNUMBER(P40)), "적 합", "부적합") ) -> 부적합 | S40: 반복성 | T40: =IF( OR( COUNTBLANK(T37:T39) > 0, COUNTBLANK(V37:V39) > 0, ISTEXT(MAX(STDEV(T37:T39), STDEV(V37:V39))), ISBLANK(MAX(STDEV(T37:T39), STDEV(V37:V39))) ), "", ROUND(MAX(STDEV(T37:T39), STDEV(V37:V39)), 2) ) | U40: 결과 | V40: =IF( OR( ISBLANK(T40), ISTEXT(T40), ISERROR(T40), T40 > 0.1 ), "부적합", IF(AND(T40 <= 0.1, ISNUMBER(T40)), "적 합", "부적합") ) -> 부적합 | Y40: 반복성 | Z40: =IF( OR( COUNTBLANK(Z37:Z39) > 0, ISTEXT(STDEV(Z37:Z39)), ISBLANK(STDEV(Z37:Z39)) ), "", ROUND(STDEV(Z37:Z39), 2) ) | AA40: 결과 | AB40: =IF( OR( ISBLANK(Z40), ISTEXT(Z40), ISERROR(Z40), Z40 > 0.3 ), "부적합", IF( AND(Z40 <= 0.3, ISNUMBER(Z40)), "적 합", "부적합" ) ) -> 부적합 | AE40: 반복성 | AF40: =IF( OR( COUNTBLANK(AF37:AF39) > 0, COUNTBLANK(AH37:AH39) > 0, AH8 = 0, ISBLANK(AH8) ), "", ROUND(MAX(STDEV(AF37:AF39), STDEV(AH37:AH39)) / AH8 * 100, 1) ) | AG40: 결과 | AH40: =IF( OR( ISBLANK(AF40), ISTEXT(AF40), ISERROR(AF40), AF40 > 3 ), "부적합", IF(AND(AF40 <= 3, ISNUMBER(AF40)), "적 합", "부적합") ) -> 부적합
C41: Z1 | D41: =IF(OR(ISBLANK(D15), ISTEXT(D15)), "", D15) | E41: Z2 | F41: =IF(OR(ISBLANK(D16), ISTEXT(D16)), "", D16) | G41: Z1 | H41: =IF(OR(ISBLANK(H15), ISTEXT(H15)), "", H15) | I41: Z2 | J41: =IF(OR(ISBLANK(H16), ISTEXT(H16)), "", H16) | K41: Z1 | L41: =IF(OR(ISBLANK(L15), ISTEXT(L15)), "", L15) | M41: Z2 | N41: =IF(OR(ISBLANK(L16), ISTEXT(L16)), "", L16) | O41: Z1 | P41: =IF(OR(ISBLANK(P15), ISTEXT(P15)), "", P15) | Q41: Z2 | R41: =IF(OR(ISBLANK(P16), ISTEXT(P16)), "", P16) | S41: 시험초기 | T41: =IF(OR(ISBLANK(U21), ISTEXT(U21)), "", U21) | U41: 2시간후 | V41: =IF(OR(ISBLANK(X21), ISTEXT(X21)), "", X21) | Y41: 시험초기 | Z41: =IF(OR(ISBLANK(AA18), ISTEXT(AA18)), "", AA18) | AA41: 2시간후 | AB41: =IF(OR(ISBLANK(AD18), ISTEXT(AD18)), "", AD18) | AE41: Z1 | AF41: =IF(OR(ISBLANK(AF15), ISTEXT(AF15)), "", AF15) | AG41: Z2 | AH41: =IF(OR(ISBLANK(AF16), ISTEXT(AF16)), "", AF16)
C42: Z3 | D42: =IF(OR(ISBLANK(D20), ISTEXT(D20)), "", D20) | E42: Z4 | F42: =IF(OR(ISBLANK(D21), ISTEXT(D21)), "", D21) | G42: Z3 | H42: =IF(OR(ISBLANK(H20), ISTEXT(H20)), "", H20) | I42: Z4 | J42: =IF(OR(ISBLANK(H21), ISTEXT(H21)), "", H21) | K42: Z3 | L42: =IF(OR(ISBLANK(L20), ISTEXT(L20)), "", L20) | M42: Z4 | N42: =IF(OR(ISBLANK(L21), ISTEXT(L21)), "", L21) | O42: Z3 | P42: =IF(OR(ISBLANK(P20), ISTEXT(P20)), "", P20) | Q42: Z4 | R42: =IF(OR(ISBLANK(P21), ISTEXT(P21)), "", P21) | T42: =IF(OR(ISBLANK(U22), ISTEXT(U22)), "", U22) | V42: =IF(OR(ISBLANK(X22), ISTEXT(X22)), "", X22) | Z42: =IF(OR(ISBLANK(AA19), ISTEXT(AA19)), "", AA19) | AB42: =IF(OR(ISBLANK(AD19), ISTEXT(AD19)), "", AD19) | AE42: Z3 | AF42: =IF(OR(ISBLANK(AF20), ISTEXT(AF20)), "", AF20) | AG42: Z4 | AH42: =IF(OR(ISBLANK(AF21), ISTEXT(AF21)), "", AF21)
C43: 제로드리프트 | D43: =IF( OR( COUNTBLANK(D41:F42)>0, F8=0, ISBLANK(F8) ), "", ROUND(ABS(AVERAGE(D41,F41)-AVERAGE(D42,F42))/F8*100,1) ) | E43: 결과 | F43: =IF( OR( ISBLANK(D43), ISERROR(D43), D43 <= 5 ), IF( OR( ISBLANK(D43), ISTEXT(D43) ), "부적합", "적 합" ), "부적합" ) -> 부적합 | G43: 제로드리프트 | H43: =IF( OR( COUNTBLANK(H41:J42) > 0, J8 = 0, ISBLANK(J8) ), "", ROUND(ABS(AVERAGE(H41,J41)-AVERAGE(H42,J42))/J8*100,1) ) | I43: 결과 | J43: =IF( OR( ISBLANK(H43), ISERROR(H43), H43 <= 5 ), IF( OR( ISBLANK(H43), ISTEXT(H43) ), "부적합", "적 합" ), "부적합" ) -> 부적합 | K43: 제로드리프트 | L43: =IF( OR( COUNTBLANK(L41:N42) > 0, N8 = 0, ISBLANK(N8) ), "", ROUND(ABS(AVERAGE(L41,N41)-AVERAGE(L42,N42))/N8*100,1) ) | M43: 결과 | N43: =IF( OR( ISBLANK(L43), ISERROR(L43), L43 <= 5 ), IF( OR( ISBLANK(L43), ISTEXT(L43) ), "부적합", "적 합" ), "부적합" ) -> 부적합 | O43: 제로드리프트 | P43: =IF( OR( COUNTBLANK(P41:R42) > 0, R8 = 0, ISBLANK(R8) ), "", ROUND(ABS(AVERAGE(P41,R41)-AVERAGE(P42,R42))/R8*100,1) ) | Q43: 결과 | R43: =IF( OR( ISBLANK(P43), ISERROR(P43), P43 <= 5 ), IF( OR( ISBLANK(P43), ISTEXT(P43) ), "부적합", "적 합" ), "부적합" ) -> 부적합 | T43: =IF(OR(ISBLANK(U23), ISTEXT(U23)), "", U23) | V43: =IF(OR(ISBLANK(X23), ISTEXT(X23)), "", X23) | Z43: =IF(OR(ISBLANK(AA20), ISTEXT(AA20)), "", AA20) | AB43: =IF(OR(ISBLANK(AD20), ISTEXT(AD20)), "", AD20) | AE43: 제로드리프트 | AF43: =IF( OR( COUNTBLANK(AF41:AH42) > 0, AH8 = 0, ISBLANK(AH8) ), "", ROUND(ABS(AVERAGE(AF41:AH41) - AVERAGE(AF42:AH42)) / AH8 * 100, 1) ) | AG43: 결과 | AH43: =IF( OR( ISBLANK(AF43), ISERROR(AF43), AF43 <= 5 ), IF( OR( ISBLANK(AF43), ISTEXT(AF43) ), "부적합", "적 합" ), "부적합" ) -> 부적합
C44: S1 | D44: =IF(OR(ISBLANK(D17), ISTEXT(D17)), "", D17) | E44: S2 | F44: =IF(OR(ISBLANK(D18), ISTEXT(D18)), "", D18) | G44: S1 | H44: =IF(OR(ISBLANK(H17), ISTEXT(H17)), "", H17) | I44: S2 | J44: =IF(OR(ISBLANK(H18), ISTEXT(H18)), "", H18) | K44: S1 | L44: =IF(OR(ISBLANK(L17), ISTEXT(L17)), "", L17) | M44: S2 | N44: =IF(OR(ISBLANK(L18), ISTEXT(L18)), "", L18) | O44: S1 | P44: =IF(OR(ISBLANK(P17), ISTEXT(P17)), "", P17) | Q44: S2 | R44: =IF(OR(ISBLANK(P18), ISTEXT(P18)), "", P18) | S44: 제로드리프트 | T44: =IF( OR( COUNTBLANK(V41:V43) > 0, COUNTBLANK(T41:T43) > 0, ISBLANK(AVERAGE(V41:V43)), ISTEXT(MAX(AVERAGE(V41:V43), AVERAGE(T41:T43))) ), "", IF( ISTEXT(MAX(AVERAGE(V41:V43), AVERAGE(T41:T43))), "", ROUND(ABS(AVERAGE(V41:V43) - AVERAGE(T41:T43)), 2) ) ) | U44: 결과 | V44: =IF(OR(ISBLANK(T44), ISERROR(T44), T44 <= 0.1), IF(OR(ISBLANK(T44), ISTEXT(T44)), "부적합", "적 합"), "부적합") -> 부적합 | Y44: 제로드리프트 | Z44: =IF( OR( COUNTBLANK(AB41:AB43) > 0, COUNTBLANK(Z41:Z43) > 0, ISBLANK(AVERAGE(AB41:AB43)), ISTEXT(MAX(AVERAGE(AB41:AB43), AVERAGE(Z41:Z43))) ), "", IF( ISTEXT(MAX(AVERAGE(AB41:AB43), AVERAGE(Z41:Z43))), "", ROUND(ABS(AVERAGE(AB41:AB43) - AVERAGE(Z41:Z43)), 2) ) ) | AA44: 결과 | AB44: =IF( OR( ISBLANK(Z44), ISERROR(Z44), Z44 <= 0.2 ), IF( OR( ISBLANK(Z44), ISTEXT(Z44) ), "부적합", "적 합" ), "부적합" ) -> 부적합 | AE44: S1 | AF44: =IF(OR(ISBLANK(AF17), ISTEXT(AF17)), "", AF17) | AG44: S2 | AH44: =IF(OR(ISBLANK(AF18), ISTEXT(AF18)), "", AF18)
...

Sheet Sheet2
A1: 수질TMS정도검사 수분석 시트 | K1: =Sheet1!R1 -> v 9.0 청정수소인증센터 (2025.02.18)
A3: 총유기탄소 | E3: 총질소 | I3: 총인 | M3: 부유물질 | Q3: 화학적산소요구량
B4: 측정값 | C4: 주시험법 | F4: 측정값 | G4: 주시험법 | J4: 측정값 | K4: 주시험법 | N4: 측정값 | O4: 주시험법 | R4: 측정값 | S4: 주시험법
A5: 1 | E5: 1 | I5: 1 | M5: 1 | Q5: 1
A7: 2 | E7: 2 | I7: 2 | M7: 2 | Q7: 2
A9: 배출기준
A10: 측정값1(Ci) | B10: =B5 -> 0 | C10: 측정값2(Ci) | D10: =B7 -> 0
A11: 주시험1(Ai) | B11: =C5 -> 0 | C11: 주시험2(Ai) | D11: =C7 -> 0 | E11: 측정값1(Ci) | F11: =F5 -> 0 | G11: 측정값2(Ci) | H11: =F7 -> 0 | I11: 측정값1(Ci) | J11: =J5 -> 0 | K11: 측정값2(Ci) | L11: =J7 -> 0 | M11: 측정값1(Ci) | N11: =N5 -> 0 | O11: 측정값2(Ci) | P11: =N7 -> 0 | Q11: 측정값1(Ci) | R11: =R5 -> 0 | S11: 측정값2(Ci) | T11: =R7 -> 0
B12: =C6 -> 0 | D12: =C8 -> 0 | E12: 주시험1(Ai) | F12: =G5 -> 0 | G12: 주시험2(Ai) | H12: =G7 -> 0 | I12: 주시험1(Ai) | J12: =K5 -> 0 | K12: 주시험2(Ai) | L12: =K7 -> 0 | M12: 주시험1(Ai) | N12: =O5 -> 0 | O12: 주시험2(Ai) | P12: =O7 -> 0 | Q12: 주시험1(Ai) | R12: =S5 -> 0 | S12: 주시험2(Ai) | T12: =S7 -> 0
A13: 수분석 총평균 | B13: =SUM(C5:D8)/4 -> 0 | F13: =G6 -> 0 | H13: =G8 -> 0 | J13: =K6 -> 0 | L13: =K8 -> 0 | N13: =O6 -> 0 | P13: =O8 -> 0 | R13: =S6 -> 0 | T13: =S8 -> 0
A14: Ai 평균 | B14: =AVERAGE(B11:B12) -> 0 | C14: Ai 평균 | D14: =AVERAGE(D11:D12) -> 0 | E14: 수분석 총평균 | F14: =SUM(G5:H8)/4 -> 0 | I14: 수분석 총평균 | J14: =SUM(K5:L8)/4 -> 0 | M14: 수분석 총평균 | N14: =SUM(O5:P8)/4 -> 0 | Q14: 수분석 총평균 | R14: =SUM(S5:T8)/4 -> 0
A15: │오차│(Fi) | B15: =ABS(B14-B10) -> 0 | C15: │오차│(Fi) | D15: =ABS(D14-D10) -> 0 | E15: Ai 평균 | F15: =AVERAGE(F12:F13) -> 0 | G15: Ai 평균 | H15: =AVERAGE(H12:H13) -> 0 | I15: Ai 평균 | J15: =AVERAGE(J12:J13) -> 0 | K15: Ai 평균 | L15: =AVERAGE(L12:L13) -> 0 | M15: Ai 평균 | N15: =AVERAGE(N12:N13) -> 0 | O15: Ai 평균 | P15: =AVERAGE(P12:P13) -> 0 | Q15: Ai 평균 | R15: =AVERAGE(R12:R13) -> 0 | S15: Ai 평균 | T15: =AVERAGE(T12:T13) -> 0
A16: mg/L | B16: =ROUND((B15+D15)/2,2) -> 0 | E16: │오차│(Fi) | F16: =ABS(F15-F11) -> 0 | G16: │오차│(Fi) | H16: =ABS(H15-H11) -> 0 | I16: │오차│(Fi) | J16: =ABS(J15-J11) -> 0 | K16: │오차│(Fi) | L16: =ABS(L15-L11) -> 0 | M16: │오차│(Fi) | N16: =ABS(N15-N11) -> 0 | O16: │오차│(Fi) | P16: =ABS(P15-P11) -> 0 | Q16: │오차│(Fi) | R16: =ABS(R15-R11) -> 0 | S16: │오차│(Fi) | T16: =ABS(T15-T11) -> 0
A17: Fi/Ai(평균) | B17: =B15/B14 -> #DIV/0! | C17: Fi/Ai(평균) | D17: =D15/D14 -> #DIV/0! | E17: mg/L | F17: =ROUND((F16+H16)/2,2) -> 0 | I17: mg/L | J17: =ROUND((J16+L16)/2,3) -> 0 | M17: mg/L | N17: =ROUND((N16+P16)/2,1) -> 0 | Q17: mg/L | R17: =ROUND((R16+T16)/2,1) -> 0
A18: % | B18: =ROUND((B17+D17)/2*100,1) -> #DIV/0! | E18: Fi/Ai(평균) | F18: =F16/F15 -> #DIV/0! | G18: Fi/Ai(평균) | H18: =H16/H15 -> #DIV/0! | I18: Fi/Ai(평균) | J18: =J16/J15 -> #DIV/0! | K18: Fi/Ai(평균) | L18: =L16/L15 -> #DIV/0! | M18: Fi/Ai(평균) | N18: =N16/N15 -> #DIV/0! | O18: Fi/Ai(평균) | P18: =P16/P15 -> #DIV/0! | Q18: Fi/Ai(평균) | R18: =R16/R15 -> #DIV/0! | S18: Fi/Ai(평균) | T18: =T16/T15 -> #DIV/0!
A19: 배출기준(%) | B19: =IFERROR(ROUND(B16/B9*100,1),"해당 없음") -> 해당 없음 | E19: % | F19: =ROUND((F18+H18)/2*100,1) -> #DIV/0! | I19: % | J19: =ROUND((J18+L18)/2*100,1) -> #DIV/0! | M19: % | N19: =ROUND((N18+P18)/2*100,1) -> #DIV/0! | Q19: % | R19: =ROUND((R18+T18)/2*100,1) -> #DIV/0!
A20: 현장적용 계수시험 | B20: =IFERROR(IF(AND(B9="",B13<=3),TEXT(B16,"0.00")&" mg/L",IF(B13<B9/2,TEXT(B19,"0.0")&" %",TEXT(B18,"0.0")&" %")),"") -> 0.00 mg/L | C20: 결과 | D20: =IFERROR(IF(OR(B5="-",B7="-"),"부적합",IF(OR(B5="_",B7="_"),"해당 없음",IF(B13<B9/2,IF(B19<=15,"적 합","부적합"),IF(B13<3,IF(B16<=0.45,"적 합","부적합"),IF(B18<=15,"적 합","부적합"))))),"") -> 적 합 | E20: 현장적용 계수시험 | F20: =IFERROR(IF(F14<10,TEXT(F17,"0.00")&" mg/L",TEXT(F19,"0.0")&" %"),"") -> 0.00 mg/L | G20: 결과 | H20: =IFERROR(IF(OR(F5="-",F7="-"),"부적합",IF(OR(F5="_",F7="_"),"해당 없음",IF(F14<10,IF(F17<=1.5,"적 합","부적합"),IF(F19<=15,"적 합","부적합")))),"") -> 적 합 | I20: 현장적용 계수시험 | J20: =IFERROR(IF(J14<0.4,TEXT(J17,"0.000")&" mg/L",TEXT(J19,"0.0")&" %"),"") -> 0.000 mg/L | K20: 결과 | L20: =IFERROR(IF(OR(J5="-",J7="-"),"부적합",IF(OR(J5="_",J7="_"),"해당 없음",IF(J14<0.4,IF(J17<=0.06,"적 합","부적합"),IF(J19<=15,"적 합","부적합")))),"") -> 적 합 | M20: 현장적용 계수시험 | N20: =IFERROR(IF(N14<=5,TEXT(N17,"0.0")&" mg/L",TEXT(N19,"0.0")&" %"),"") -> 0.0 mg/L | O20: 결과 | P20: =IFERROR(IF(OR(N5="-",N7="-"),"부적합",IF(OR(N5="_",N7="_"),"해당 없음",IF(N14<5,IF(N17<=1,"적 합","부적합"),IF(N19<=20,"적 합","부적합")))),"") -> 적 합 | Q20: 현장적용 계수시험 | R20: =IFERROR(IF(R14<=20,TEXT(R17,"0.0")&" mg/L",TEXT(R19,"0.0")&" %"),"") -> 0.0 mg/L | S20: 결과 | T20: =IFERROR(IF(OR(R5="-",R7="-"),"부적합",IF(OR(R5="_",R7="_"),"해당 없음",IF(R14<20,IF(R17<=3,"적 합","부적합"),IF(R19<=15,"적 합","부적합")))),"") -> 적 합
A22: =IF(B13<(B9/2),"배출기준에 의한 식으로 구하여 15.0 % 이하","주시험법 기준농도의 15.0 % 또는 0.45 mg/L(측정값이 3.0 mg/L 이하에 적용) 이하") -> 주시험법 기준농도의 15.0 % 또는 0.45 mg/L(측정값이 3.0 mg/L 이하에 적용) 이하

Sheet Sheet3
A1: 순서 | B1: pH | W1: 측정순서 | X1: ph
B2: 1회 | X2: 노란테이블에서 가져올 데이터 | Y2: 순서에 맞게 뽑은 데이터 | AA2: ph경우의수
A3: 1 | W3: 7 | X3: =IF(B3="","",B3) | Y3: =IF(W2=AA3,X30,IF(W2=AA4,X30,IF(W2=AA5,X30,IF(W2=AA6,X30,IF(W2=AA7,X30,IF(W2=AA8,X30,IF(W2=AA9,X9,IF(W2=AA10,X9,IF(W2=AA11,X9,IF(W2=AA12,X9,IF(W2=AA13,X9,IF(W2=AA14,X9,IF(W2=AA15,X18,IF(W2=AA16,X18,IF(W2=AA17,X18,IF(W2=AA18,X18,IF(W2=AA19,X18,IF(W2=AA20,X18,IF(W2=AA21,X3,IF(W2=AA22,X3,IF(W2=AA23,X3,IF(W2=AA24,X3,IF(W2=AA25,X3,IF(W2=AA26,X3,"")))))))))))))))))))))))) | Z3: 1 | AA3: 44444444777101010444777444777747474
A4: 2 | I4: 수질 | W4: 4 | X4: =IF(B4="","",B4) | Y4: =IF(W2=AA3,X31,IF(W2=AA4,X31,IF(W2=AA5,X31,IF(W2=AA6,X31,IF(W2=AA7,X31,IF(W2=AA8,X31,IF(W2=AA9,X10,IF(W2=AA10,X10,IF(W2=AA11,X10,IF(W2=AA12,X10,IF(W2=AA13,X10,IF(W2=AA14,X10,IF(W2=AA15,X19,IF(W2=AA16,X19,IF(W2=AA17,X19,IF(W2=AA18,X19,IF(W2=AA19,X19,IF(W2=AA20,X19,IF(W2=AA21,X4,IF(W2=AA22,X4,IF(W2=AA23,X4,IF(W2=AA24,X4,IF(W2=AA25,X4,IF(W2=AA26,X4,"")))))))))))))))))))))))) | Z4: 2 | AA4: 44444444777101010747474444777444777
A5: 3 | I5: 측정값 | J5: 수분석 | W5: 7 | X5: =IF(B5="","",B5) | Y5: =IF(W2=AA3,X32,IF(W2=AA4,X32,IF(W2=AA5,X32,IF(W2=AA6,X32,IF(W2=AA7,X32,IF(W2=AA8,X32,IF(W2=AA9,X11,IF(W2=AA10,X11,IF(W2=AA11,X11,IF(W2=AA12,X11,IF(W2=AA13,X11,IF(W2=AA14,X11,IF(W2=AA15,X20,IF(W2=AA16,X20,IF(W2=AA17,X20,IF(W2=AA18,X20,IF(W2=AA19,X20,IF(W2=AA20,X20,IF(W2=AA21,X5,IF(W2=AA22,X5,IF(W2=AA23,X5,IF(W2=AA24,X5,IF(W2=AA25,X5,IF(W2=AA26,X5,"")))))))))))))))))))))))) | Z5: 3 | AA5: 44444444777444777444777101010747474
A6: 4 | W6: 4 | X6: =IF(B6="","",B6) | Y6: =IF(W2=AA3,X33,IF(W2=AA4,X33,IF(W2=AA5,X33,IF(W2=AA6,X33,IF(W2=AA7,X33,IF(W2=AA8,X33,IF(W2=AA9,X12,IF(W2=AA10,X12,IF(W2=AA11,X12,IF(W2=AA12,X12,IF(W2=AA13,X12,IF(W2=AA14,X12,IF(W2=AA15,X21,IF(W2=AA16,X21,IF(W2=AA17,X21,IF(W2=AA18,X21,IF(W2=AA19,X21,IF(W2=AA20,X21,IF(W2=AA21,X6,IF(W2=AA22,X6,IF(W2=AA23,X6,IF(W2=AA24,X6,IF(W2=AA25,X6,IF(W2=AA26,X6,"")))))))))))))))))))))))) | Z6: 4 | AA6: 44444444777444777747474444777101010
A7: 5 | W7: 7 | X7: =IF(B7="","",B7) | Y7: =IF(W2=AA3,X34,IF(W2=AA4,X34,IF(W2=AA5,X34,IF(W2=AA6,X34,IF(W2=AA7,X34,IF(W2=AA8,X34,IF(W2=AA9,X13,IF(W2=AA10,X13,IF(W2=AA11,X13,IF(W2=AA12,X13,IF(W2=AA13,X13,IF(W2=AA14,X13,IF(W2=AA15,X22,IF(W2=AA16,X22,IF(W2=AA17,X22,IF(W2=AA18,X22,IF(W2=AA19,X22,IF(W2=AA20,X22,IF(W2=AA21,X7,IF(W2=AA22,X7,IF(W2=AA23,X7,IF(W2=AA24,X7,IF(W2=AA25,X7,IF(W2=AA26,X7,"")))))))))))))))))))))))) | Z7: 5 | AA7: 44444747474444777101010444777444777
A8: 6 | W8: 4 | X8: =IF(B8="","",B8) | Y8: =IF(W2=AA3,X9,IF(W2=AA4,X9,IF(W2=AA5,X18,IF(W2=AA6,X18,IF(W2=AA7,X3,IF(W2=AA8,X3,IF(W2=AA9,X14,IF(W2=AA10,X14,IF(W2=AA11,X14,IF(W2=AA12,X14,IF(W2=AA13,X14,IF(W2=AA14,X14,IF(W2=AA15,X23,IF(W2=AA16,X23,IF(W2=AA17,X23,IF(W2=AA18,X23,IF(W2=AA19,X23,IF(W2=AA20,X23,IF(W2=AA21,X8,IF(W2=AA22,X8,IF(W2=AA23,X8,IF(W2=AA24,X8,IF(W2=AA25,X8,IF(W2=AA26,X8,"")))))))))))))))))))))))) | Z8: 6 | AA8: 44444747474444777444777444777101010
A9: 7 | W9: 4 | X9: =IF(B21="","",B21) | Y9: =IF(W2=AA3,X10,IF(W2=AA4,X10,IF(W2=AA5,X19,IF(W2=AA6,X19,IF(W2=AA7,X4,IF(W2=AA8,X4,IF(W2=AA9,X15,IF(W2=AA10,X15,IF(W2=AA11,X15,IF(W2=AA12,X15,IF(W2=AA13,X15,IF(W2=AA14,X15,IF(W2=AA15,X24,IF(W2=AA16,X24,IF(W2=AA17,X24,IF(W2=AA18,X24,IF(W2=AA19,X24,IF(W2=AA20,X24,IF(W2=AA21,X30,IF(W2=AA22,X30,IF(W2=AA23,X9,IF(W2=AA24,X9,IF(W2=AA25,X18,IF(W2=AA26,X18,"")))))))))))))))))))))))) | Z9: 7 | AA9: 44477710101044444444777444777747474
A10: 8 | W10: 4 | X10: =IF(B22="","",B22) | Y10: =IF(W2=AA3,X11,IF(W2=AA4,X11,IF(W2=AA5,X20,IF(W2=AA6,X20,IF(W2=AA7,X5,IF(W2=AA8,X5,IF(W2=AA9,X16,IF(W2=AA10,X16,IF(W2=AA11,X16,IF(W2=AA12,X16,IF(W2=AA13,X16,IF(W2=AA14,X16,IF(W2=AA15,X25,IF(W2=AA16,X25,IF(W2=AA17,X25,IF(W2=AA18,X25,IF(W2=AA19,X25,IF(W2=AA20,X25,IF(W2=AA21,X31,IF(W2=AA22,X31,IF(W2=AA23,X10,IF(W2=AA24,X10,IF(W2=AA25,X19,IF(W2=AA26,X19,"")))))))))))))))))))))))) | Z10: 8 | AA10: 44477710101044444747474444777444777
A11: 9 | P11: I11 | W11: 4 | X11: =IF(B23="","",B23) | Y11: =IF(W2=AA3,X12,IF(W2=AA4,X12,IF(W2=AA5,X21,IF(W2=AA6,X21,IF(W2=AA7,X6,IF(W2=AA8,X6,IF(W2=AA9,X17,IF(W2=AA10,X17,IF(W2=AA11,X17,IF(W2=AA12,X17,IF(W2=AA13,X17,IF(W2=AA14,X17,IF(W2=AA15,X26,IF(W2=AA16,X26,IF(W2=AA17,X26,IF(W2=AA18,X26,IF(W2=AA19,X26,IF(W2=AA20,X26,IF(W2=AA21,X32,IF(W2=AA22,X32,IF(W2=AA23,X11,IF(W2=AA24,X11,IF(W2=AA25,X20,IF(W2=AA26,X20,"")))))))))))))))))))))))) | Z11: 9 | AA11: 44477710101044477744477744444747474
A12: 10 | W12: 7 | X12: =IF(B24="","",B24) | Y12: =IF(W2=AA3,X13,IF(W2=AA4,X13,IF(W2=AA5,X22,IF(W2=AA6,X22,IF(W2=AA7,X7,IF(W2=AA8,X7,IF(W2=AA9,X30,IF(W2=AA10,X30,IF(W2=AA11,X18,IF(W2=AA12,X18,IF(W2=AA13,X3,IF(W2=AA14,X3,IF(W2=AA15,X27,IF(W2=AA16,X27,IF(W2=AA17,X27,IF(W2=AA18,X27,IF(W2=AA19,X27,IF(W2=AA20,X27,IF(W2=AA21,X33,IF(W2=AA22,X33,IF(W2=AA23,X12,IF(W2=AA24,X12,IF(W2=AA25,X21,IF(W2=AA26,X21,"")))))))))))))))))))))))) | Z12: 10 | AA12: 44477710101044477744477774747444444
A13: 11 | W13: 7 | X13: =IF(B25="","",B25) | Y13: =IF(W2=AA3,X14,IF(W2=AA4,X14,IF(W2=AA5,X23,IF(W2=AA6,X23,IF(W2=AA7,X8,IF(W2=AA8,X8,IF(W2=AA9,X31,IF(W2=AA10,X31,IF(W2=AA11,X19,IF(W2=AA12,X19,IF(W2=AA13,X4,IF(W2=AA14,X4,IF(W2=AA15,X28,IF(W2=AA16,X28,IF(W2=AA17,X28,IF(W2=AA18,X28,IF(W2=AA19,X28,IF(W2=AA20,X28,IF(W2=AA21,X34,IF(W2=AA22,X34,IF(W2=AA23,X13,IF(W2=AA24,X13,IF(W2=AA25,X22,IF(W2=AA26,X22,"")))))))))))))))))))))))) | Z13: 11 | AA13: 44477710101074747444444444777444777
A14: 12 | W14: 7 | X14: =IF(B26="","",B26) | Y14: =IF(W2=AA3,X15,IF(W2=AA4,X15,IF(W2=AA5,X24,IF(W2=AA6,X24,IF(W2=AA7,X9,IF(W2=AA8,X18,IF(W2=AA9,X32,IF(W2=AA10,X32,IF(W2=AA11,X20,IF(W2=AA12,X20,IF(W2=AA13,X5,IF(W2=AA14,X5,IF(W2=AA15,X29,IF(W2=AA16,X29,IF(W2=AA17,X29,IF(W2=AA18,X29,IF(W2=AA19,X29,IF(W2=AA20,X29,IF(W2=AA21,X9,IF(W2=AA22,X18,IF(W2=AA23,X14,IF(W2=AA24,X14,IF(W2=AA25,X23,IF(W2=AA26,X23,"")))))))))))))))))))))))) | Z14: 12 | AA14: 44477710101074747444477744477744444
A15: 13 | W15: 10 | X15: =IF(B27="","",B27) | Y15: =IF(W2=AA3,X16,IF(W2=AA4,X16,IF(W2=AA5,X25,IF(W2=AA6,X25,IF(W2=AA7,X10,IF(W2=AA8,X19,IF(W2=AA9,X33,IF(W2=AA10,X33,IF(W2=AA11,X21,IF(W2=AA12,X21,IF(W2=AA13,X6,IF(W2=AA14,X6,IF(W2=AA15,X30,IF(W2=AA16,X30,IF(W2=AA17,X9,IF(W2=AA18,X9,IF(W2=AA19,X3,IF(W2=AA20,X3,IF(W2=AA21,X10,IF(W2=AA22,X19,IF(W2=AA23,X15,IF(W2=AA24,X15,IF(W2=AA25,X24,IF(W2=AA26,X24,"")))))))))))))))))))))))) | Z15: 13 | AA15: 44477744477744444444777101010747474
A16: 14 | W16: 10 | X16: =IF(B28="","",B28) | Y16: =IF(W2=AA3,X17,IF(W2=AA4,X17,IF(W2=AA5,X26,IF(W2=AA6,X26,IF(W2=AA7,X11,IF(W2=AA8,X20,IF(W2=AA9,X34,IF(W2=AA10,X34,IF(W2=AA11,X22,IF(W2=AA12,X22,IF(W2=AA13,X7,IF(W2=AA14,X7,IF(W2=AA15,X31,IF(W2=AA16,X31,IF(W2=AA17,X10,IF(W2=AA18,X10,IF(W2=AA19,X4,IF(W2=AA20,X4,IF(W2=AA21,X11,IF(W2=AA22,X20,IF(W2=AA23,X16,IF(W2=AA24,X16,IF(W2=AA25,X25,IF(W2=AA26,X25,"")))))))))))))))))))))))) | Z16: 14 | AA16: 44477744477744444747474444777101010
A17: 15 | W17: 10 | X17: =IF(B29="","",B29) | Y17: =IF(W2=AA3,X18,IF(W2=AA4,X3,IF(W2=AA5,X27,IF(W2=AA6,X27,IF(W2=AA7,X12,IF(W2=AA8,X21,IF(W2=AA9,X18,IF(W2=AA10,X3,IF(W2=AA11,X23,IF(W2=AA12,X23,IF(W2=AA13,X8,IF(W2=AA14,X8,IF(W2=AA15,X32,IF(W2=AA16,X32,IF(W2=AA17,X11,IF(W2=AA18,X11,IF(W2=AA19,X5,IF(W2=AA20,X5,IF(W2=AA21,X12,IF(W2=AA22,X21,IF(W2=AA23,X17,IF(W2=AA24,X17,IF(W2=AA25,X26,IF(W2=AA26,X26,"")))))))))))))))))))))))) | Z17: 15 | AA17: 44477744477744477710101044444747474
A18: 16 | W18: 4 | X18: =IF(B9="","",B9) | Y18: =IF(W2=AA3,X19,IF(W2=AA4,X4,IF(W2=AA5,X28,IF(W2=AA6,X28,IF(W2=AA7,X13,IF(W2=AA8,X22,IF(W2=AA9,X19,IF(W2=AA10,X4,IF(W2=AA11,X24,IF(W2=AA12,X24,IF(W2=AA13,X30,IF(W2=AA14,X18,IF(W2=AA15,X33,IF(W2=AA16,X33,IF(W2=AA17,X12,IF(W2=AA18,X12,IF(W2=AA19,X6,IF(W2=AA20,X6,IF(W2=AA21,X13,IF(W2=AA22,X22,IF(W2=AA23,X30,IF(W2=AA24,X18,IF(W2=AA25,X27,IF(W2=AA26,X27,"")))))))))))))))))))))))) | Z18: 16 | AA18: 44477744477744477710101074747444444
A19: 17 | W19: 4 | X19: =IF(B10="","",B10) | Y19: =IF(W2=AA3,X20,IF(W2=AA4,X5,IF(W2=AA5,X29,IF(W2=AA6,X29,IF(W2=AA7,X14,IF(W2=AA8,X23,IF(W2=AA9,X20,IF(W2=AA10,X5,IF(W2=AA11,X25,IF(W2=AA12,X25,IF(W2=AA13,X31,IF(W2=AA14,X19,IF(W2=AA15,X34,IF(W2=AA16,X34,IF(W2=AA17,X13,IF(W2=AA18,X13,IF(W2=AA19,X7,IF(W2=AA20,X7,IF(W2=AA21,X14,IF(W2=AA22,X23,IF(W2=AA23,X31,IF(W2=AA24,X19,IF(W2=AA25,X28,IF(W2=AA26,X28,"")))))))))))))))))))))))) | Z19: 17 | AA19: 44477744477774747444444444777101010
A20: 18 | W20: 4 | X20: =IF(B11="","",B11) | Y20: =IF(W2=AA3,X21,IF(W2=AA4,X6,IF(W2=AA5,X9,IF(W2=AA6,X3,IF(W2=AA7,X15,IF(W2=AA8,X24,IF(W2=AA9,X21,IF(W2=AA10,X6,IF(W2=AA11,X26,IF(W2=AA12,X26,IF(W2=AA13,X32,IF(W2=AA14,X20,IF(W2=AA15,X9,IF(W2=AA16,X3,IF(W2=AA17,X14,IF(W2=AA18,X14,IF(W2=AA19,X8,IF(W2=AA20,X8,IF(W2=AA21,X15,IF(W2=AA22,X24,IF(W2=AA23,X32,IF(W2=AA24,X20,IF(W2=AA25,X29,IF(W2=AA26,X29,"")))))))))))))))))))))))) | Z20: 18 | AA20: 44477744477774747444477710101044444
A21: 19 | W21: 7 | X21: =IF(B12="","",B12) | Y21: =IF(W2=AA3,X22,IF(W2=AA4,X7,IF(W2=AA5,X10,IF(W2=AA6,X4,IF(W2=AA7,X16,IF(W2=AA8,X25,IF(W2=AA9,X22,IF(W2=AA10,X7,IF(W2=AA11,X27,IF(W2=AA12,X27,IF(W2=AA13,X33,IF(W2=AA14,X21,IF(W2=AA15,X10,IF(W2=AA16,X4,IF(W2=AA17,X15,IF(W2=AA18,X15,IF(W2=AA19,X30,IF(W2=AA20,X9,IF(W2=AA21,X16,IF(W2=AA22,X25,IF(W2=AA23,X33,IF(W2=AA24,X21,IF(W2=AA25,X30,IF(W2=AA26,X9,"")))))))))))))))))))))))) | Z21: 19 | AA21: 74747444444444777101010444777444777
A22: 20 | W22: 7 | X22: =IF(B13="","",B13) | Y22: =IF(W2=AA3,X23,IF(W2=AA4,X8,IF(W2=AA5,X11,IF(W2=AA6,X5,IF(W2=AA7,X17,IF(W2=AA8,X26,IF(W2=AA9,X23,IF(W2=AA10,X8,IF(W2=AA11,X28,IF(W2=AA12,X28,IF(W2=AA13,X34,IF(W2=AA14,X22,IF(W2=AA15,X11,IF(W2=AA16,X5,IF(W2=AA17,X16,IF(W2=AA18,X16,IF(W2=AA19,X31,IF(W2=AA20,X10,IF(W2=AA21,X17,IF(W2=AA22,X26,IF(W2=AA23,X34,IF(W2=AA24,X22,IF(W2=AA25,X31,IF(W2=AA26,X10,"")))))))))))))))))))))))) | Z22: 20 | AA22: 74747444444444777444777444777101010
A23: 21 | W23: 7 | X23: =IF(B14="","",B14) | Y23: =IF(W2=AA3,X24,IF(W2=AA4,X18,IF(W2=AA5,X12,IF(W2=AA6,X6,IF(W2=AA7,X18,IF(W2=AA8,X27,IF(W2=AA9,X24,IF(W2=AA10,X18,IF(W2=AA11,X29,IF(W2=AA12,X29,IF(W2=AA13,X18,IF(W2=AA14,X23,IF(W2=AA15,X12,IF(W2=AA16,X6,IF(W2=AA17,X17,IF(W2=AA18,X17,IF(W2=AA19,X32,IF(W2=AA20,X11,IF(W2=AA21,X18,IF(W2=AA22,X27,IF(W2=AA23,X18,IF(W2=AA24,X23,IF(W2=AA25,X32,IF(W2=AA26,X11,"")))))))))))))))))))))))) | Z23: 21 | AA23: 74747444477710101044444444777444777
A24: 22 | W24: 4 | X24: =IF(B15="","",B15) | Y24: =IF(W2=AA3,X25,IF(W2=AA4,X19,IF(W2=AA5,X13,IF(W2=AA6,X7,IF(W2=AA7,X19,IF(W2=AA8,X28,IF(W2=AA9,X25,IF(W2=AA10,X19,IF(W2=AA11,X30,IF(W2=AA12,X3,IF(W2=AA13,X19,IF(W2=AA14,X24,IF(W2=AA15,X13,IF(W2=AA16,X7,IF(W2=AA17,X30,IF(W2=AA18,X3,IF(W2=AA19,X33,IF(W2=AA20,X12,IF(W2=AA21,X19,IF(W2=AA22,X28,IF(W2=AA23,X19,IF(W2=AA24,X24,IF(W2=AA25,X33,IF(W2=AA26,X12,"")))))))))))))))))))))))) | Z24: 22 | AA24: 74747444477710101044477744477744444
A25: 23 | W25: 4 | X25: =IF(B16="","",B16) | Y25: =IF(W2=AA3,X26,IF(W2=AA4,X20,IF(W2=AA5,X14,IF(W2=AA6,X8,IF(W2=AA7,X20,IF(W2=AA8,X29,IF(W2=AA9,X26,IF(W2=AA10,X20,IF(W2=AA11,X31,IF(W2=AA12,X4,IF(W2=AA13,X20,IF(W2=AA14,X25,IF(W2=AA15,X14,IF(W2=AA16,X8,IF(W2=AA17,X31,IF(W2=AA18,X4,IF(W2=AA19,X34,IF(W2=AA20,X13,IF(W2=AA21,X20,IF(W2=AA22,X29,IF(W2=AA23,X20,IF(W2=AA24,X25,IF(W2=AA25,X34,IF(W2=AA26,X13,"")))))))))))))))))))))))) | Z25: 23 | AA25: 74747444477744477744444444777101010
A26: 24 | W26: 4 | X26: =IF(B17="","",B17) | Y26: =IF(W2=AA3,X27,IF(W2=AA4,X21,IF(W2=AA5,X15,IF(W2=AA6,X9,IF(W2=AA7,X21,IF(W2=AA8,X9,IF(W2=AA9,X27,IF(W2=AA10,X21,IF(W2=AA11,X32,IF(W2=AA12,X5,IF(W2=AA13,X21,IF(W2=AA14,X26,IF(W2=AA15,X15,IF(W2=AA16,X9,IF(W2=AA17,X32,IF(W2=AA18,X5,IF(W2=AA19,X9,IF(W2=AA20,X14,IF(W2=AA21,X21,IF(W2=AA22,X9,IF(W2=AA23,X21,IF(W2=AA24,X26,IF(W2=AA25,X9,IF(W2=AA26,X14,"")))))))))))))))))))))))) | Z26: 24 | AA26: 74747444477744477744477710101044444
A27: 25 | V27: I27 | W27: 7 | X27: =IF(B18="","",B18) | Y27: =IF(W2=AA3,X28,IF(W2=AA4,X22,IF(W2=AA5,X16,IF(W2=AA6,X10,IF(W2=AA7,X22,IF(W2=AA8,X10,IF(W2=AA9,X28,IF(W2=AA10,X22,IF(W2=AA11,X33,IF(W2=AA12,X6,IF(W2=AA13,X22,IF(W2=AA14,X27,IF(W2=AA15,X16,IF(W2=AA16,X10,IF(W2=AA17,X33,IF(W2=AA18,X6,IF(W2=AA19,X10,IF(W2=AA20,X15,IF(W2=AA21,X22,IF(W2=AA22,X10,IF(W2=AA23,X22,IF(W2=AA24,X27,IF(W2=AA25,X10,IF(W2=AA26,X15,""))))))))))))))))))))))))
A28: 26 | W28: 7 | X28: =IF(B19="","",B19) | Y28: =IF(W2=AA3,X29,IF(W2=AA4,X23,IF(W2=AA5,X17,IF(W2=AA6,X11,IF(W2=AA7,X23,IF(W2=AA8,X11,IF(W2=AA9,X29,IF(W2=AA10,X23,IF(W2=AA11,X34,IF(W2=AA12,X7,IF(W2=AA13,X23,IF(W2=AA14,X28,IF(W2=AA15,X17,IF(W2=AA16,X11,IF(W2=AA17,X34,IF(W2=AA18,X7,IF(W2=AA19,X11,IF(W2=AA20,X16,IF(W2=AA21,X23,IF(W2=AA22,X11,IF(W2=AA23,X23,IF(W2=AA24,X28,IF(W2=AA25,X11,IF(W2=AA26,X16,""))))))))))))))))))))))))
A29: 27 | W29: 7 | X29: =IF(B20="","",B20) | Y29: =IF(W2=AA3,X3,IF(W2=AA4,X24,IF(W2=AA5,X3,IF(W2=AA6,X12,IF(W2=AA7,X24,IF(W2=AA8,X12,IF(W2=AA9,X3,IF(W2=AA10,X24,IF(W2=AA11,X3,IF(W2=AA12,X8,IF(W2=AA13,X24,IF(W2=AA14,X29,IF(W2=AA15,X3,IF(W2=AA16,X12,IF(W2=AA17,X3,IF(W2=AA18,X8,IF(W2=AA19,X12,IF(W2=AA20,X17,IF(W2=AA21,X24,IF(W2=AA22,X12,IF(W2=AA23,X24,IF(W2=AA24,X29,IF(W2=AA25,X12,IF(W2=AA26,X17,""))))))))))))))))))))))))
A30: 28 | W30: 4 | X30: =IF(B30="","",B30) | Y30: =IF(W2=AA3,X4,IF(W2=AA4,X25,IF(W2=AA5,X4,IF(W2=AA6,X13,IF(W2=AA7,X25,IF(W2=AA8,X13,IF(W2=AA9,X4,IF(W2=AA10,X25,IF(W2=AA11,X4,IF(W2=AA12,X30,IF(W2=AA13,X25,IF(W2=AA14,X30,IF(W2=AA15,X4,IF(W2=AA16,X13,IF(W2=AA17,X4,IF(W2=AA18,X30,IF(W2=AA19,X13,IF(W2=AA20,X30,IF(W2=AA21,X25,IF(W2=AA22,X13,IF(W2=AA23,X25,IF(W2=AA24,X30,IF(W2=AA25,X13,IF(W2=AA26,X30,""))))))))))))))))))))))))
A31: 29 | W31: 4 | X31: =IF(B31="","",B31) | Y31: =IF(W2=AA3,X5,IF(W2=AA4,X26,IF(W2=AA5,X5,IF(W2=AA6,X14,IF(W2=AA7,X26,IF(W2=AA8,X14,IF(W2=AA9,X5,IF(W2=AA10,X26,IF(W2=AA11,X5,IF(W2=AA12,X31,IF(W2=AA13,X26,IF(W2=AA14,X31,IF(W2=AA15,X5,IF(W2=AA16,X14,IF(W2=AA17,X5,IF(W2=AA18,X31,IF(W2=AA19,X14,IF(W2=AA20,X31,IF(W2=AA21,X26,IF(W2=AA22,X14,IF(W2=AA23,X26,IF(W2=AA24,X31,IF(W2=AA25,X14,IF(W2=AA26,X31,""))))))))))))))))))))))))
A32: 30 | W32: 4 | X32: =IF(B32="","",B32) | Y32: =IF(W2=AA3,X6,IF(W2=AA4,X27,IF(W2=AA5,X6,IF(W2=AA6,X15,IF(W2=AA7,X27,IF(W2=AA8,X15,IF(W2=AA9,X6,IF(W2=AA10,X27,IF(W2=AA11,X6,IF(W2=AA12,X32,IF(W2=AA13,X27,IF(W2=AA14,X32,IF(W2=AA15,X6,IF(W2=AA16,X15,IF(W2=AA17,X6,IF(W2=AA18,X32,IF(W2=AA19,X15,IF(W2=AA20,X32,IF(W2=AA21,X27,IF(W2=AA22,X15,IF(W2=AA23,X27,IF(W2=AA24,X32,IF(W2=AA25,X15,IF(W2=AA26,X32,""))))))))))))))))))))))))
A33: 31 | W33: 4 | X33: =IF(B33="","",B33) | Y33: =IF(W2=AA3,X7,IF(W2=AA4,X28,IF(W2=AA5,X7,IF(W2=AA6,X16,IF(W2=AA7,X28,IF(W2=AA8,X16,IF(W2=AA9,X7,IF(W2=AA10,X28,IF(W2=AA11,X7,IF(W2=AA12,X33,IF(W2=AA13,X28,IF(W2=AA14,X33,IF(W2=AA15,X7,IF(W2=AA16,X16,IF(W2=AA17,X7,IF(W2=AA18,X33,IF(W2=AA19,X16,IF(W2=AA20,X33,IF(W2=AA21,X28,IF(W2=AA22,X16,IF(W2=AA23,X28,IF(W2=AA24,X33,IF(W2=AA25,X16,IF(W2=AA26,X33,""))))))))))))))))))))))))
A34: 32 | W34: 4 | X34: =IF(B34="","",B34) | Y34: =IF(W2=AA3,X8,IF(W2=AA4,X29,IF(W2=AA5,X8,IF(W2=AA6,X17,IF(W2=AA7,X29,IF(W2=AA8,X17,IF(W2=AA9,X8,IF(W2=AA10,X29,IF(W2=AA11,X8,IF(W2=AA12,X34,IF(W2=AA13,X29,IF(W2=AA14,X34,IF(W2=AA15,X8,IF(W2=AA16,X17,IF(W2=AA17,X8,IF(W2=AA18,X34,IF(W2=AA19,X17,IF(W2=AA20,X34,IF(W2=AA21,X29,IF(W2=AA22,X17,IF(W2=AA23,X29,IF(W2=AA24,X34,IF(W2=AA25,X17,IF(W2=AA26,X34,""))))))))))))))))))))))))
A38: 순서 | B38: TOC, TN, TP, SS, COD (mg/L) | W38: 측정순서 | X38: TOC,TN,TP,SS
B39: 1회 | X39: 노란테이블에서 가져올 데이터 | Y39: 순서에 맞게 뽑은 데이터
A40: 1 | W40: M1 | X40: =IF(B40="","",B40) | Y40: =IF(MID(W39,1,4)="zszz",X43,IF(MID(W39,1,4)="szss",X44,IF(MID(W39,1,4)="zzss",X45,IF(MID(W39,1,4)="sszz",X47,IF(MID(W39,1,5)="MMMZS",X40,IF(MID(W39,1,5)="MMMZZ",X40,IF(MID(W39,1,4)="ZSMM",X43,IF(MID(W39,1,4)="SZMM",X44,IF(MID(W39,1,5)="MMMSS",X40,IF(MID(W39,1,5)="MMMSZ",X40,X40))))))))))
A41: 2 | W41: M2 | X41: =IF(B41="","",B41) | Y41: =IF(MID(W39,1,4)="zszz",X44,IF(MID(W39,1,4)="szss",X43,IF(MID(W39,1,4)="zzss",X46,IF(MID(W39,1,4)="sszz",X48,IF(MID(W39,1,5)="MMMZS",X41,IF(MID(W39,1,5)="MMMZZ",X41,IF(MID(W39,1,4)="ZSMM",X44,IF(MID(W39,1,4)="SZMM",X43,IF(MID(W39,1,5)="MMMSS",X41,IF(MID(W39,1,5)="MMMSZ",X41,X41))))))))))
A42: 3 | W42: M3 | X42: =IF(B42="","",B42) | Y42: =IF(MID(W39,1,4)="zszz",X45,IF(MID(W39,1,4)="szss",X47,IF(MID(W39,1,4)="zzss",X47,IF(MID(W39,1,4)="sszz",X45,IF(MID(W39,1,5)="MMMZS",X42,IF(MID(W39,1,5)="MMMZZ",X42,IF(MID(W39,1,4)="ZSMM",X40,IF(MID(W39,1,4)="SZMM",X40,IF(MID(W39,1,5)="MMMSS",X42,IF(MID(W39,1,5)="MMMSZ",X42,X42))))))))))
A43: 4 | W43: Z5 | X43: =IF(B51="","",B51) | Y43: =IF(MID(W39,1,4)="zszz",X46,IF(MID(W39,1,4)="szss",X48,IF(MID(W39,1,4)="zzss",X48,IF(MID(W39,1,4)="sszz",X46,IF(MID(W39,1,5)="MMMZS",X43,IF(MID(W39,1,5)="MMMZZ",X45,IF(MID(W39,1,4)="ZSMM",X41,IF(MID(W39,1,4)="SZMM",X41,IF(MID(W39,1,5)="MMMSS",X47,IF(MID(W39,1,5)="MMMSZ",X44,X43))))))))))
...

Sheet Sheet4
A1: 먹는물 정도검사 시트 | E1: =Sheet1!R1 -> v 9.0 청정수소인증센터 (2025.02.18)
A3: 탁도 | E3: 잔류염소
A4: O Test Condition
A5: 측정범위 | B5: 0 | C5: ~ | E5: 측정범위 | F5: 0 | G5: ~
A6: O DATA Sheet
A7: Z1 | E7: =A7 -> Z1
A8: Z2 | E8: =A8 -> Z2
A9: S1 | E9: =A9 -> S1
A10: S2 | E10: =A10 -> S2
A11: Z(2hr)
A12: Z3 | E12: =A12 -> Z3
A13: Z4 | E13: =A13 -> Z4
A14: S3 | E14: =A14 -> S3
A15: S4 | E15: =A15 -> S4
A16: Z5 | E16: =A16 -> Z5
A17: 응답시간 (mm) | E17: 응답시간(mm)
A18: S5 | E18: =A18 -> S5
A19: M | E19: =A19 -> M
A20: 탁도 Data | E20: 잔류염소 Data
A21: Z5 | B21: =IF(B16="","",B16) | C21: S5 | D21: =IF(B18="","",B18) | E21: Z5 | F21: =IF(F16="","",F16) | G21: S5 | H21: =IF(F18="","",F18)
A22: =IF(B22=B7,"Z1","Z2") -> Z1 | B22: =IF( OR( ISBLANK(B7), ISBLANK(B8), ISBLANK(B12), ISBLANK(B13), ISBLANK(B16) ), "", IF( OR( STDEV(B7,B12,B16) = MAX(STDEV(B7,B12,B16),STDEV(B8,B13,B16),STDEV(B7,B13,B16),STDEV(B8,B12,B16)), STDEV(B7,B13,B16) = MAX(STDEV(B7,B12,B16),STDEV(B8,B13,B16),STDEV(B7,B13,B16),STDEV(B8,B12,B16)) ), B7, IF( STDEV(B8,B13,B16) = MAX(STDEV(B7,B12,B16),STDEV(B8,B13,B16),STDEV(B7,B13,B16),STDEV(B8,B12,B16)), B8, IF( STDEV(B8,B12,B16) = MAX(STDEV(B7,B12,B16),STDEV(B8,B13,B16),STDEV(B7,B13,B16),STDEV(B8,B12,B16)), B8, "" ) ) ) ) | C22: =IF(D22=B9,"S1","S2") -> S1 | D22: =IF( OR( ISBLANK(B9), ISBLANK(B10), ISBLANK(B14), ISBLANK(B15), ISBLANK(B18) ), "", IF( OR( STDEV(B9,B14,B18) = MAX(STDEV(B9,B14,B18),STDEV(B10,B15,B18),STDEV(B9,B15,B18),STDEV(B10,B14,B18)), STDEV(B9,B15,B18) = MAX(STDEV(B9,B14,B18),STDEV(B10,B15,B18),STDEV(B9,B15,B18),STDEV(B10,B14,B18)) ), B9, IF( STDEV(B10,B15,B18) = MAX(STDEV(B9,B14,B18),STDEV(B10,B15,B18),STDEV(B9,B15,B18),STDEV(B10,B14,B18)), B10, IF( STDEV(B10,B14,B18) = MAX(STDEV(B9,B14,B18),STDEV(B10,B15,B18),STDEV(B9,B15,B18),STDEV(B10,B14,B18)), B10, "" ) ) ) ) | E22: =IF(F22=F7,"Z1","Z2") -> Z1 | F22: =IF( OR( ISBLANK(F7), ISBLANK(F8), ISBLANK(F12), ISBLANK(F13), ISBLANK(F16) ), "", IF( OR( STDEV(F7,F12,F16) = MAX(STDEV(F7,F12,F16),STDEV(F8,F13,F16),STDEV(F7,F13,F16),STDEV(F8,F12,F16)), STDEV(F7,F13,F16) = MAX(STDEV(F7,F12,F16),STDEV(F8,F13,F16),STDEV(F7,F13,F16),STDEV(F8,F12,F16)) ), F7, IF( STDEV(F8,F13,F16) = MAX(STDEV(F7,F12,F16),STDEV(F8,F13,F16),STDEV(F7,F13,F16),STDEV(F8,F12,F16)), F8, IF( STDEV(F8,F12,F16) = MAX(STDEV(F7,F12,F16),STDEV(F8,F13,F16),STDEV(F7,F13,F16),STDEV(F8,F12,F16)), F8, "" ) ) ) ) | G22: =IF(H22=F9,"S1","S2") -> S1 | H22: =IF( OR( ISBLANK(F9), ISBLANK(F10), ISBLANK(F14), ISBLANK(F15), ISBLANK(F18) ), "", IF( MAX( STDEV(F9,F14,F18),STDEV(F10,F15,F18),STDEV(F9,F15,F18),STDEV(F10,F14,F18) ) = STDEV(F9,F14,F18), F9, IF( MAX( STDEV(F9,F14,F18),STDEV(F10,F15,F18),STDEV(F9,F15,F18),STDEV(F10,F14,F18) ) = STDEV(F9,F15,F18), F9, IF( MAX( STDEV(F9,F14,F18),STDEV(F10,F15,F18),STDEV(F9,F15,F18),STDEV(F10,F14,F18) ) = STDEV(F10,F15,F18), F10, IF( MAX( STDEV(F9,F14,F18),STDEV(F10,F15,F18),STDEV(F9,F15,F18),STDEV(F10,F14,F18) ) = STDEV(F10,F14,F18), F10, "" ) ) ) ) )
A23: =IF(B23=B12,"Z3","Z4") -> Z3 | B23: =IF( OR( ISBLANK(B7), ISBLANK(B8), ISBLANK(B12), ISBLANK(B13), ISBLANK(B16) ), "", IF( OR( STDEV(B7,B12,B16) = MAX(STDEV(B7,B12,B16),STDEV(B8,B13,B16),STDEV(B7,B13,B16),STDEV(B8,B12,B16)), STDEV(B8,B12,B16) = MAX(STDEV(B7,B12,B16),STDEV(B8,B13,B16),STDEV(B7,B13,B16),STDEV(B8,B12,B16)) ), B12, IF( STDEV(B7,B13,B16) = MAX(STDEV(B7,B12,B16),STDEV(B8,B13,B16),STDEV(B7,B13,B16),STDEV(B8,B12,B16)), B13, IF( STDEV(B8,B13,B16) = MAX(STDEV(B7,B12,B16),STDEV(B8,B13,B16),STDEV(B7,B13,B16),STDEV(B8,B12,B16)), B13, "" ) ) ) ) | C23: =IF(D23=B14,"S3","S4") -> S3 | D23: =IF( OR( ISBLANK(B9), ISBLANK(B10), ISBLANK(B14), ISBLANK(B15), ISBLANK(B18) ), "", IF( OR( STDEV(B9,B14,B18) = MAX(STDEV(B9,B14,B18),STDEV(B10,B15,B18),STDEV(B9,B15,B18),STDEV(B10,B14,B18)), STDEV(B10,B14,B18) = MAX(STDEV(B9,B14,B18),STDEV(B10,B15,B18),STDEV(B9,B15,B18),STDEV(B10,B14,B18)) ), B14, IF( STDEV(B9,B15,B18) = MAX(STDEV(B9,B14,B18),STDEV(B10,B15,B18),STDEV(B9,B15,B18),STDEV(B10,B14,B18)), B15, IF( STDEV(B10,B15,B18) = MAX(STDEV(B9,B14,B18),STDEV(B10,B15,B18),STDEV(B9,B15,B18),STDEV(B10,B14,B18)), B15, "" ) ) ) ) | E23: =IF(F23=F12,"Z3","Z4") -> Z3 | F23: =IF( OR( ISBLANK(F7), ISBLANK(F8), ISBLANK(F12), ISBLANK(F13), ISBLANK(F16) ), "", IF( MAX( STDEV(F7,F12,F16),STDEV(F8,F13,F16),STDEV(F7,F13,F16),STDEV(F8,F12,F16) ) = STDEV(F7,F12,F16), F12, IF( MAX( STDEV(F7,F12,F16),STDEV(F8,F13,F16),STDEV(F7,F13,F16),STDEV(F8,F12,F16) ) = STDEV(F7,F13,F16), F13, IF( MAX( STDEV(F7,F12,F16),STDEV(F8,F13,F16),STDEV(F7,F13,F16),STDEV(F8,F12,F16) ) = STDEV(F8,F13,F16), F13, IF( MAX( STDEV(F7,F12,F16),STDEV(F8,F13,F16),STDEV(F7,F13,F16),STDEV(F8,F12,F16) ) = STDEV(F8,F12,F16), F12, "" ) ) ) ) ) | G23: =IF(H23=F14,"S3","S4") -> S3 | H23: =IF( OR( ISBLANK(F9), ISBLANK(F10), ISBLANK(F14), ISBLANK(F15), ISBLANK(F18) ), "", IF( MAX( STDEV(F9,F14,F18),STDEV(F10,F15,F18),STDEV(F9,F15,F18),STDEV(F10,F14,F18) ) = STDEV(F9,F14,F18), F14, IF( MAX( STDEV(F9,F14,F18),STDEV(F10,F15,F18),STDEV(F9,F15,F18),STDEV(F10,F14,F18) ) = STDEV(F9,F15,F18), F15, IF( MAX( STDEV(F9,F14,F18),STDEV(F10,F15,F18),STDEV(F9,F15,F18),STDEV(F10,F14,F18) ) = STDEV(F10,F15,F18), F15, IF( MAX( STDEV(F9,F14,F18),STDEV(F10,F15,F18),STDEV(F9,F15,F18),STDEV(F10,F14,F18) ) = STDEV(F10,F14,F18), F14, "" ) ) ) ) )
A24: 반복성 | B24: =IF( OR( COUNTBLANK(B21:B23)>0, COUNTBLANK(D21:D23)>0, D5=0, ISBLANK(D5) ), "", ROUND(MAX(STDEV(B21:B23),STDEV(D21:D23))/D5*100,1) ) | C24: 결 과 | D24: =IF(OR(ISBLANK(B24), NOT(ISNUMBER(B24)), B24>2), "부적합", "적 합") -> 부적합 | E24: 반복성 | F24: =IF(OR(COUNTBLANK(F21:F23)>0, COUNTBLANK(H21:H23)>0, H5=0, H5=""), "", ROUND(MAX(STDEV(F21:F23),STDEV(H21:H23))/H5*100,1)) | G24: 결 과 | H24: =IF(OR(ISBLANK(F24), NOT(ISNUMBER(F24)), F24>2), "부적합", "적 합") -> 부적합
A25: Z1 | B25: =IF(B7="","",B7) | C25: Z2 | D25: =IF(B8="","",B8) | E25: Z1 | F25: =IF(F7="","",F7) | G25: Z2 | H25: =IF(F8="","",F8)
A26: Z3 | B26: =IF(B12="","",B12) | C26: Z4 | D26: =IF(B13="","",B13) | E26: Z3 | F26: =IF(F12="","",F12) | G26: Z4 | H26: =IF(F13="","",F13)
A27: 제로드리프트 | B27: =IF( OR( ISBLANK(B7), ISBLANK(B8), ISBLANK(B12), ISBLANK(B13), ISBLANK(D5), D5 = "" ), "", IFERROR( ROUND(ABS(AVERAGE(B7,B8)-AVERAGE(B12,B13))/D5*100,1), "" ) ) | C27: 결 과 | D27: =IF( OR( ISBLANK(B27), ISTEXT(B27) ), "부적합", IF( B27 <= 3, "적 합", "부적합" ) ) -> 부적합 | E27: 제로드리프트 | F27: =IF( OR( ISBLANK(F7), ISBLANK(F8), ISBLANK(F12), ISBLANK(F13), ISBLANK(H5), H5 = "" ), "", IFERROR( ROUND(ABS(AVERAGE(F7,F8)-AVERAGE(F12,F13))/H5*100,1), "" ) ) | G27: 결 과 | H27: =IF( OR( ISBLANK(F27), ISTEXT(F27) ), "부적합", IF( F27 <= 3, "적 합", "부적합" ) ) -> 부적합
A28: S1 | B28: =IF(B9="","",B9) | C28: S2 | D28: =IF(B10="","",B10) | E28: S1 | F28: =IF(F9="","",F9) | G28: S2 | H28: =IF(F10="","",F10)
A29: S3 | B29: =IF(B14="","",B14) | C29: S4 | D29: =IF(B15="","",B15) | E29: S3 | F29: =IF(F14="","",F14) | G29: S4 | H29: =IF(F15="","",F15)
A30: 스팬드리프트 | B30: =IF( OR( ISBLANK(B9), ISBLANK(B10), ISBLANK(B14), ISBLANK(B15), ISBLANK(D5), D5 = "" ), "", IFERROR( ROUND(ABS(AVERAGE(B9,B10)-AVERAGE(B14,B15))/D5*100,1), "" ) ) | C30: 결 과 | D30: =IF( OR( ISBLANK(B30), ISTEXT(B30), ), "부적합", IF( B30 <= 3, "적 합", "부적합" ) ) -> 부적합 | E30: 스팬드리프트 | F30: =IF( OR( ISBLANK(F9), ISBLANK(F10), ISBLANK(F14), ISBLANK(F15), ISBLANK(H5), H5 = "" ), "", IFERROR( ROUND(ABS(AVERAGE(F9,F10)-AVERAGE(F14,F15))/H5*100,1), "" ) ) | G30: 결 과 | H30: =IF( OR( ISBLANK(F30), ISTEXT(F30) ), "부적합", IF( F30 <= 3, "적 합", "부적합" ) ) -> 부적합
A31: 주입농도값 | B31: =IFERROR(ROUND(IF(B9="","",B9),1)/2,"") | E31: =A31 -> 주입농도값 | F31: =IFERROR(ROUND(IF(F9="","",F9)/2,2),"")
A32: M | B32: =IF(B19="","",B19) | E32: M | F32: =IF(F19="","",F19)
A33: 직선성 | B33: =IF( OR( ISBLANK(B31), ISBLANK(B32), B31 = "", B32 = "" ), "", ROUND(ABS(B31-B32)/B31*100,1) ) | C33: 결 과 | D33: =IF( OR( ISBLANK(B33), B33 = "" ), "부적합", IF( B33 <= 5, "적 합", "부적합" ) ) -> 부적합 | E33: 직선성 | F33: =IF( OR( ISBLANK(F31), ISBLANK(F32), F31 = "", F32 = "" ), "", ROUND(ABS(F31-F32)/F31*100,1) ) | G33: 결 과 | H33: =IF( OR( ISBLANK(F33), F33 = "" ), "부적합", IF( F33 <= 5, "적 합", "부적합" ) ) -> 부적합
A34: (mm) | B34: =IF(B17="","",B17) | E34: (mm) | F34: =IF(F17="","",F17)
A35: 초 | B35: =IFERROR(IF(B17="","",B17*6),"-") | D35: =IF(D17="","",D17) | E35: 초 | F35: =IFERROR(IF(F17="","",F17*6),"-") | H35: =IF(H17="","",H17)
A36: 응답시간 | B36: =IF(B35<>"", B35 & " 초", IF(D35<>"", D35 & " 초", "")) | C36: 결 과 | D36: =IF(B36="시 약 식", "해당 없음", IF(OR(AND(B35<=600, ISNUMBER(B35)), AND(D35<=600, ISNUMBER(D35))), "적 합", "부적합")) -> 부적합 | E36: 응답시간 | F36: =IF(OR(F35="-", H35="-"), "시 약 식", IF(F35<>"", F35 & " 초", "") & IF(H35<>"", H35 & " 초", "")) | G36: 결 과 | H36: =IF(F36="시 약 식", "해당 없음", IF(OR(AND(ISNUMBER(F35), F35<=120), AND(ISNUMBER(H35), H35<=120)), "적 합", "부적합")) -> 부적합

Sheet Sheet5
A1: 국내 여비 | B1: 일비 | C1: 식비 | D1: 숙박비 | E1: 서울특별시 | F1: 광역시 | G1: 그 밖의 지역 | L1: TOC | M1: DO | N1: =H4 -> 421000
B2: 25000 | C2: 25000 | E2: 100000 | F2: 80000 | G2: 70000 | L2: TN | M2: COD | N2: =G4 -> 851000
A3: 항목 | B3: TOC | C3: TN | D3: TP | E3: SS | F3: PH | G3: COD | H3: DO | L3: TP | M3: COD, DO | N3: =G4+H4 -> 1272000
A4: 수수료 | B4: 854000 | C4: 851000 | D4: 851000 | E4: 698000 | F4: 651000 | G4: 851000 | H4: 421000 | L4: SS | M4: PH | N4: =F4 -> 651000
A5: 시험 항목 | B5: 현장 주소 | D5: 특별시/광역시 | E5: 출장 기간 | F5: 출장비 | G5: 수수료 | H5: 총합 | L5: PH | M5: PH, DO | N5: =F4+H4 -> 1072000
D6: =IF(MID(B6,3,3)="광역시","광역시",IF(MID(B6,3,3)="특별시","특별시","그 밖의 지역")) -> 그 밖의 지역 | F6: =IF(AND(E6="1박 2일",D6="특별시")=TRUE,B10,IF(AND(E6="2박 3일",D6="특별시")=TRUE,C10,IF(AND(E6="3박 4일",D6="특별시")=TRUE,D10,IF(AND(E6="4박 5일",D6="특별시")=TRUE,E10,IF(AND(E6="1박 2일",D6="광역시")=TRUE,B13,IF(AND(E6="2박 3일",D6="광역시")=TRUE,C13,IF(AND(E6="3박 4일",D6="광역시")=TRUE,D13,IF(AND(E6="4박 5일",D6="광역시")=TRUE,E13,IF(AND(E6="1박 2일",D6="그 밖의 지역")=TRUE,B16,IF(AND(E6="2박 3일",D6="그 밖의 지역")=TRUE,C16,IF(AND(E6="3박 4일",D6="그 밖의 지역")=TRUE,D16,IF(AND(E6="4박 5일",D6="그 밖의 지역")=TRUE,E16,IF(E6="1일",A10,0))))))))))))) -> 0 | G6: =VLOOKUP(A6,M1:N132,2,FALSE) -> #N/A | H6: =(F6+G6)*1.1 -> #N/A | L6: COD | M6: PH, COD | N6: =SUM(F4,G4) -> 1502000
L7: DO | M7: PH, COD, DO | N7: =F4+G4+H4 -> 1923000
A8: 서울특별시 | M8: SS | N8: =E4 -> 698000
A9: 1일 | B9: 1박 2일 | C9: 2박 3일 | D9: 3박 4일 | E9: 4박 5일 | M9: SS, DO | N9: =E4+H4 -> 1119000
A10: 50000 | B10: =E2+(2*(B2+C2)) -> 200000 | C10: =(2*E2)+(3*(B2+C2)) -> 350000 | D10: =(3*E2)+(4*(B2+C2)) -> 500000 | E10: =(4*E2)+(5*(B2+C2)) -> 650000 | M10: SS, COD | N10: =E4+G4 -> 1549000
A11: 광역시 | M11: SS, COD, DO | N11: =E4+G4+H4 -> 1970000
A12: 1일 | B12: 1박 2일 | C12: 2박 3일 | D12: 3박 4일 | E12: 4박 5일 | M12: SS, PH | N12: =E4+F4 -> 1349000
A13: 50000 | B13: =F2+(2*(B2+C2)) -> 180000 | C13: =(2*F2)+(3*(B2+C2)) -> 310000 | D13: =(3*F2)+(4*(B2+C2)) -> 440000 | E13: =(4*F2)+(5*(B2+C2)) -> 570000 | M13: SS, PH, DO | N13: =E4+F4+H4 -> 1770000
A14: 그 밖의 지역 | M14: SS, PH, COD | N14: =E4+F4+G4 -> 2200000
A15: 1일 | B15: 1박 2일 | C15: 2박 3일 | D15: 3박 4일 | E15: 4박 5일 | M15: SS, PH, COD, DO | N15: =E4+F4+G4+H4 -> 2621000
A16: 50000 | B16: =G2+(2*(B2+C2)) -> 170000 | C16: =(2*G2)+(3*(B2+C2)) -> 290000 | D16: =(3*G2)+(4*(B2+C2)) -> 410000 | E16: =(4*G2)+(5*(B2+C2)) -> 530000 | M16: TP | N16: =D4 -> 851000
A17: (1)수수료 계산 | B17: (2)수수료 계산 | C17: (3)수수료 계산 | D17: (4)수수료 계산 | E17: 총 합계 수수료 | M17: TP, DO | N17: =D4+H4 -> 1272000
E18: =SUM(A18:D18) -> 0 | M18: TP, COD | N18: =D4+G4 -> 1702000
A19: 항목 | B19: 탁도 | C19: 잔류염소 | D19: 탁도/잔류염소 | M19: TP, COD, DO | N19: =D4+G4+H4 -> 2123000
A20: 수수료 | B20: 497000 | C20: 499000 | D20: 996000 | M20: TP, PH | N20: =D4+F4 -> 1502000
A21: 시험 항목 | B21: 건수 | C21: 현장 주소 | D21: 특별시/광역시 | E21: 출장 기간 | F21: 출장비 | G21: 수수료 | H21: 총합 | M21: TP, PH, DO | N21: =D4+F4+H4 -> 1923000
A22: TU | D22: =IF(MID(C22,3,3)="광역시","광역시",IF(MID(C22,3,3)="특별시","특별시","그 밖의 지역")) -> 그 밖의 지역 | F22: =IF(AND(E22="1박 2일",D22="특별시")=TRUE,B10,IF(AND(E22="2박 3일",D22="특별시")=TRUE,C10,IF(AND(E22="3박 4일",D22="특별시")=TRUE,D10,IF(AND(E22="4박 5일",D22="특별시")=TRUE,E10,IF(AND(E22="1박 2일",D22="광역시")=TRUE,B13,IF(AND(E22="2박 3일",D22="광역시")=TRUE,C13,IF(AND(E22="3박 4일",D22="광역시")=TRUE,D13,IF(AND(E22="4박 5일",D22="광역시")=TRUE,E13,IF(AND(E22="1박 2일",D22="그 밖의 지역")=TRUE,B16,IF(AND(E22="2박 3일",D22="그 밖의 지역")=TRUE,C16,IF(AND(E22="3박 4일",D22="그 밖의 지역")=TRUE,D16,IF(AND(E22="4박 5일",D22="그 밖의 지역")=TRUE,E16,IF(E22="1일",A10,0))))))))))))) -> 0 | G22: =IF(A22="TU",B20*B22,IF(A22="TU/Cl",D20*B22,C20*B22)) -> 0 | H22: =(F22+G22)*1.1 -> 0 | M22: TP, PH, COD | N22: =D4+F4+G4 -> 2353000
A23: Cl | D23: =IF(MID(C22,3,3)="광역시","광역시",IF(MID(C22,3,3)="특별시","특별시","그 밖의 지역")) -> 그 밖의 지역 | F23: =IF(AND(E23="1박 2일",D23="특별시")=TRUE,B10,IF(AND(E23="2박 3일",D23="특별시")=TRUE,C10,IF(AND(E23="3박 4일",D23="특별시")=TRUE,D10,IF(AND(E23="4박 5일",D23="특별시")=TRUE,E10,IF(AND(E23="1박 2일",D23="광역시")=TRUE,B13,IF(AND(E23="2박 3일",D23="광역시")=TRUE,C13,IF(AND(E23="3박 4일",D23="광역시")=TRUE,D13,IF(AND(E23="4박 5일",D23="광역시")=TRUE,E13,IF(AND(E23="1박 2일",D23="그 밖의 지역")=TRUE,B16,IF(AND(E23="2박 3일",D23="그 밖의 지역")=TRUE,C16,IF(AND(E23="3박 4일",D23="그 밖의 지역")=TRUE,D16,IF(AND(E23="4박 5일",D23="그 밖의 지역")=TRUE,E16,IF(E23="1일",A10,0))))))))))))) -> 0 | G23: =IF(A23="TU",B20*B23,IF(A23="TU/Cl",D20*B23,C20*B23)) -> 0 | H23: =(F23+G23)*1.1 -> 0
A24: TU/Cl | D24: =IF(MID(C22,3,3)="광역시","광역시",IF(MID(C22,3,3)="특별시","특별시","그 밖의 지역")) -> 그 밖의 지역 | F24: =IF(AND(E24="1박 2일",D24="특별시")=TRUE,B10,IF(AND(E24="2박 3일",D24="특별시")=TRUE,C10,IF(AND(E24="3박 4일",D24="특별시")=TRUE,D10,IF(AND(E24="4박 5일",D24="특별시")=TRUE,E10,IF(AND(E24="1박 2일",D24="광역시")=TRUE,B13,IF(AND(E24="2박 3일",D24="광역시")=TRUE,C13,IF(AND(E24="3박 4일",D24="광역시")=TRUE,D13,IF(AND(E24="4박 5일",D24="광역시")=TRUE,E13,IF(AND(E24="1박 2일",D24="그 밖의 지역")=TRUE,B16,IF(AND(E24="2박 3일",D24="그 밖의 지역")=TRUE,C16,IF(AND(E24="3박 4일",D24="그 밖의 지역")=TRUE,D16,IF(AND(E24="4박 5일",D24="그 밖의 지역")=TRUE,E16,IF(E24="1일",A10,0))))))))))))) -> 0 | G24: =IF(A24="TU",B20*B24,IF(A24="TU/Cl",D20*B24,C20*B24)) -> 0 | H24: =(F24+G24)*1.1 -> 0
D25: =IF(MID(C22,3,3)="광역시","광역시",IF(MID(C22,3,3)="특별시","특별시","그 밖의 지역")) -> 그 밖의 지역 | F25: =IF(AND(E25="1박 2일",D25="특별시")=TRUE,B10,IF(AND(E25="2박 3일",D25="특별시")=TRUE,C10,IF(AND(E25="3박 4일",D25="특별시")=TRUE,D10,IF(AND(E25="4박 5일",D25="특별시")=TRUE,E10,IF(AND(E25="1박 2일",D25="광역시")=TRUE,B13,IF(AND(E25="2박 3일",D25="광역시")=TRUE,C13,IF(AND(E25="3박 4일",D25="광역시")=TRUE,D13,IF(AND(E25="4박 5일",D25="광역시")=TRUE,E13,IF(AND(E25="1박 2일",D25="그 밖의 지역")=TRUE,B16,IF(AND(E25="2박 3일",D25="그 밖의 지역")=TRUE,C16,IF(AND(E25="3박 4일",D25="그 밖의 지역")=TRUE,D16,IF(AND(E25="4박 5일",D25="그 밖의 지역")=TRUE,E16,IF(E25="1일",A10,0))))))))))))) -> 0 | H25: 총 합계 수수료
D26: =IF(MID(C22,3,3)="광역시","광역시",IF(MID(C22,3,3)="특별시","특별시","그 밖의 지역")) -> 그 밖의 지역 | F26: =IF(AND(E26="1박 2일",D26="특별시")=TRUE,B10,IF(AND(E26="2박 3일",D26="특별시")=TRUE,C10,IF(AND(E26="3박 4일",D26="특별시")=TRUE,D10,IF(AND(E26="4박 5일",D26="특별시")=TRUE,E10,IF(AND(E26="1박 2일",D26="광역시")=TRUE,B13,IF(AND(E26="2박 3일",D26="광역시")=TRUE,C13,IF(AND(E26="3박 4일",D26="광역시")=TRUE,D13,IF(AND(E26="4박 5일",D26="광역시")=TRUE,E13,IF(AND(E26="1박 2일",D26="그 밖의 지역")=TRUE,B16,IF(AND(E26="2박 3일",D26="그 밖의 지역")=TRUE,C16,IF(AND(E26="3박 4일",D26="그 밖의 지역")=TRUE,D16,IF(AND(E26="4박 5일",D26="그 밖의 지역")=TRUE,E16,IF(E26="1일",A10,0))))))))))))) -> 0 | H26: =H22+H23+H24+((F25+F26)*1.1) -> 0
M28: TP, PH, COD, DO | N28: =D4+F4+G4+H4 -> 2774000
M29: TP, SS | N29: =D4+E4 -> 1549000
M30: TP, SS, DO | N30: =D4+E4+H4 -> 1970000
M31: TP, SS, COD | N31: =D4+E4+G4 -> 2400000
M32: TP, SS, COD, DO | N32: =D4+E4+G4+H4 -> 2821000
M33: TP, SS, PH | N33: =D4+E4+F4 -> 2200000
M34: TP, SS, PH, DO | N34: =D4+E4+F4+H4 -> 2621000
M35: TP, SS, PH, COD | N35: =D4+E4+F4+G4 -> 3051000
M36: TP, SS, PH, COD, DO | N36: =N35+H4 -> 3472000
M37: TN | N37: =C4 -> 851000
M38: TN, DO | N38: =C4+H4 -> 1272000
M39: TN, COD | N39: =C4+G4 -> 1702000
M40: TN, COD, DO | N40: =C4+G4+H4 -> 2123000
M41: TN, PH | N41: =C4+F4 -> 1502000
...

Sheet Sheet6
A1: 간이측정기 시트 v 8.0 (2025.02.18)
D3: =IF(D5="수소이온농도 측정용 간이측정기 성능인증", "수소이온농도 간이측정기", IF(D5="용존산소 측정용 간이측정기 성능인증", "용존산소 간이측정기", IF(D5="탁도 측정용 간이측정기 성능인증", "탁도 간이측정기", IF(D5="잔류염소 측정용 간이측정기 성능인증", "잔류염소 간이측정기", ""))))
A6: O Test Condition
A7: 측정범위 | D7: 0 | F7: ~ | H7: 14
A8: =IF(D3="수소이온농도 간이측정기", "pH", "") | B8: =IF(D3="용존산소 간이측정기", "mg/L", IF(D3="잔류염소 간이측정기", "mg/L", IF(D3="탁도 간이측정기", "NTU", ""))) | D8: =IF(D3="수소이온농도 간이측정기","pH 사용표준용액", IF(D3="용존산소 간이측정기","수질오염공정시험기준 표2. 용존산소포화량", IF(OR(D3="탁도 간이측정기",D3="잔류염소 간이측정기"),"사용표준용액","")))
D9: =IF(D3="수소이온농도 간이측정기","pH 4.01", IF(D3="용존산소 간이측정기","10 ℃", IF(D3="탁도 간이측정기","30 %", IF(D3="잔류염소 간이측정기","30 %","")))) | E9: =IF(D3="수소이온농도 간이측정기", 4, IF(D3="용존산소 간이측정기", 11.288, IF(OR(D3="탁도 간이측정기", D3="잔류염소 간이측정기"), H7*0.3, ""))) | F9: =IF(D3="수소이온농도 간이측정기","7.00", IF(D3="용존산소 간이측정기","20 ℃", IF(D3="탁도 간이측정기","50 %", IF(D3="잔류염소 간이측정기","50 %","")))) | G9: =IF(D3="수소이온농도 간이측정기", 7.02, IF(D3="용존산소 간이측정기", 9.0292, IF(OR(D3="탁도 간이측정기", D3="잔류염소 간이측정기"), H7*0.5, ""))) | H9: =IF(D3="수소이온농도 간이측정기","10.01", IF(D3="용존산소 간이측정기","30 ℃", IF(D3="탁도 간이측정기","80 %", IF(D3="잔류염소 간이측정기","80 %","")))) | I9: =IF(D3="수소이온농도 간이측정기", 10.06, IF(D3="용존산소 간이측정기", 7.559, IF(OR(D3="탁도 간이측정기", D3="잔류염소 간이측정기"), H7*0.8, "")))
A10: O DATA Sheet
A11: 실내시험 | D11: 기준데이터 | G11: Ⅰ | H11: Ⅱ | I11: Ⅲ
